Workbook

Sheet Summary
A1: GTT (Gaztransport & Technigaz): three-scenario DCF
A2: Valuation date 2026-10-16. €mm unless stated. Change blue/yellow cells in 'Inputs'; everything else recalculates.
B4: Bear | C4: Base | D4: Bull | E4: Prob.-weighted
A5: New orders a year 2027-35 (LNGC-eq.) | B5: =DCF!C41 -> 35 | C5: =DCF!C82 -> 60 | D5: =DCF!C123 -> 75
A6: 2026 revenue | B6: =DCF!C13 -> 736.7 | C6: =DCF!C54 -> 736.7 | D6: =DCF!C95 -> 736.7
A7: 2030 revenue | B7: =DCF!G13 -> 522.02011 | C7: =DCF!G54 -> 785.34085 | D7: =DCF!G95 -> 948.37625
A8: 2035 revenue | B8: =DCF!L13 -> 499.21965 | C8: =DCF!L54 -> 820.38263 | D8: =DCF!L95 -> 1038.1079
A9: 2030 EBITDA margin | B9: =DCF!G17 -> 0.46012155 | C9: =DCF!G58 -> 0.62396548 | D9: =DCF!G99 -> 0.67571603
A10: Enterprise value | B10: =DCF!C33 -> 1946.2974 | C10: =DCF!C74 -> 4306.5513 | D10: =DCF!C115 -> 5879.4111
A11: Value per share (€) | B11: =DCF!C37 -> 65.628277 | C11: =DCF!C78 -> 129.30362 | D11: =DCF!C119 -> 171.73651 | E11: =SUMPRODUCT(B11:D11,B14:D14) -> 123.99301
A12: Upside / (downside) | B12: =DCF!C38 -> -0.68984746 | C12: =DCF!C79 -> -0.38892429 | D12: =DCF!C120 -> -0.1883908 | E12: =E11/Inputs!B5-1 -> -0.41402171
A13: Terminal value as % of EV | B13: =DCF!C39 -> 0.27680807 | C13: =DCF!C80 -> 0.44834261 | D13: =DCF!C121 -> 0.49504469
A14: Probability | B14: =Inputs!B70 -> 0.25 | C14: =Inputs!B71 -> 0.5 | D14: =Inputs!B72 -> 0.25
A16: Current share price (€) | B16: =Inputs!B5 -> 211.6
A17: WACC | B17: =Inputs!B19 -> 0.09628076
A18: Orders a year (2027-35) needed to justify the price | B18: ='Reverse DCF'!C7 -> 96.276916
A19: 2026 revenue vs company guidance (low end) | B19: =C6/Inputs!B76-1 -> -0.0044594595
A20: Dividend yield (FY2025 dividend €8.94) | B20: =Historical!F10/Inputs!B5 -> 0.042249527
A22: Legend: blue = input, black = formula, green = link to another sheet, yellow = key assumption.
A23: Sources: GTT press releases FY2025 (2026-02-19) and H1 2026 (2026-07-28); Yahoo Finance 2026-10-16.
A24: Personal research, not investment advice.

Sheet Inputs
A1: GTT (Gaztransport & Technigaz): inputs and scenario levers (€mm unless stated)
A2: Blue = hardcoded input. Yellow = key assumption. Black = formula. Sources in column N.
A4: Market data and capital structure
A5: Share price (€) | B5: 211.6 | N5: Yahoo Finance, close 2026-10-16
A6: Shares outstanding excl. treasury (mm) | B6: 37.067 | N6: H1 2026 press release: weighted average 37,066,945 shares
A7: Cash at 30 June 2026 | B7: 384.7 | N7: H1 2026 press release, other consolidated financial data
A8: Debt at 30 June 2026 (Danelec acquisition loan) | B8: 90 | N8: H1 2026 press release
A9: Net cash | B9: =B7-B8 -> 294.7 | N9: Formula (294.7 in the press release)
A11: Discount rate
A12: Risk-free rate (French OAT 10-year) | B12: 0.0475 | N12: Trading Economics, 2026-10-07: ~4.75% (spread over Bunds at a post-2011 high)
A13: Beta | B13: 0.9 | N13: Assumption: regression beta 0.42 (Yahoo) looks too low for a business tied to shipbuilding orders
A14: Equity risk premium | B14: 0.055 | N14: Assumption (author), Europe
A15: Cost of equity | B15: =B12+B13*B14 -> 0.097 | N15: CAPM
A16: Pre-tax cost of debt | B16: 0.04 | N16: Assumption
A17: Tax rate | B17: 0.16 | N17: H1 2026 effective rate 15.2% (37.7 / 248.2); French IP box applies to royalties
A18: Market capitalisation | B18: =B5*B6 -> 7843.3772 | N18: Formula
A19: WACC | B19: =(B18*B15+B8*B16*(1-B17))/(B18+B8) -> 0.09628076 | N19: Formula, market-value weights
A21: Revenue engine and costs
A22: Royalty per LNG-carrier-equivalent order (€mm, 2026 terms) | B22: 9.5 | N22: Derived: H1 2026 orders (65 units, ~60 LNGC-equivalent) added ~€570mm to the order-book revenue schedule
A23: Royalty escalation per year | B23: 0.02 | N23: Assumption: shipbuilding price inflation
A24: Recognition: year after order | B24: 0.2 | N24: Derived from the change in the order-book schedule Dec-25 -> Jun-26: 2027 +113, 2028 +317, 2029+ +140
A25: Recognition: second year after order | B25: 0.55 | N25: Same derivation
A26: Recognition: third year after order | B26: 0.25 | N26: Same derivation
A27: Check (must be 100%) | B27: =SUM(B24:B26) -> 1 | N27: Formula
A28: Core operating costs 2026 (excl. GTT Marine) | B28: 193 | N28: H1 2026: revenue 387.3 - EBITDA 263.6 = 123.7 of costs; ~250/yr less GTT Marine costs (~57)
A29: Core cost growth per year | B29: 0.03 | N29: Assumption: wages and R&D
A30: GTT Marine revenue 2026E | B30: 70 | N30: H1 2026: 31.8 (Danelec consolidated); assumption for H2
A31: GTT Marine EBITDA margin | B31: 0.18 | N31: H1 2026: EBITDA 5.7 on revenue 31.8
A32: Services and other revenue 2026E | B32: 22 | N32: H1 2026 services 10.8; FY2025 23.0
A33: Services growth per year | B33: 0.02 | N33: Assumption
A34: D&A per year | B34: 30 | N34: H1 2026 EBITDA - EBIT = 15.4 (includes Danelec purchase-price amortisation)
A35: Capex per year (net of subsidies) | B35: 30 | N35: Assumption: H1 2026 gross 14.5 less 12.3 subsidy; 2024 68.5 incl. headquarters
A36: Change in NWC as % of change in revenue | B36: 0.1 | N36: Assumption; FY2025 working capital rose 26.4 on +161.7 revenue
A37: H2 2026 FCF as share of modelled FY2026 FCF | B37: 0.5 | N37: Cash generated after 30 June 2026, added to net cash
A39: Revenue already secured by the order book (company schedule at 30 June 2026)
C40: 2026 | D40: 2027 | E40: 2028 | F40: 2029 | G40: 2030 | H40: 2031 | I40: 2032 | J40: 2033 | K40: 2034 | L40: 2035
A41: Core business order-book revenue | C41: 644.7 | D41: 655 | E41: 603 | F41: 221.3 | G41: 73.8 | H41: 0 | I41: 0 | J41: 0 | K41: 0 | L41: 0 | N41: H1 2026 press release: 1,853 = H2-26 300 + 2027 655 + 2028 603 + 2029+ 295. 2026 = H1 actual 344.7 + 300; 2029+ split 75/25 over 2029-30 (assumption)
A43: Scenarios: new orders in LNG-carrier equivalents (2026 column = second half only)
A44: Bear case | N44: LNG shipping is over-ordered after the 2022-26 wave and competing membrane designs win share in China: 35 orders a year.
A45: New orders (units) | C45: 15 | D45: 35 | E45: 35 | F45: 35 | G45: 35 | H45: 35 | I45: 35 | J45: 35 | K45: 35 | L45: 35
...

Sheet Historical
A1: GTT: historical figures (€mm)
A2: Sources: GTT FY2025 and H1 2026 press releases; FY2021-23 from company figures via stockanalysis.com / Yahoo Finance.
A4: €mm | B4: 2021 | C4: 2022 | D4: 2023 | E4: 2024 | F4: 2025 | G4: H1 2025 | H4: H1 2026
A5: Revenue | B5: 314.7 | C5: 307.3 | D5: 427.7 | E5: 641.4 | F5: 803 | G5: 388.7 | H5: 387.3
A6: EBITDA | C6: 163.1 | D6: 241.2 | E6: 388.1 | F6: 541.8 | G6: 264.5 | H6: 263.6
A7: Operating income (EBIT) | B7: 164.6 | C7: 152.2 | D7: 232.4 | E7: 374.3 | F7: 521.3 | G7: 257.1 | H7: 248.2
A8: Net income | B8: 134.1 | C8: 128.3 | D8: 201.4 | E8: 347.8 | F8: 413.6 | G8: 180 | H8: 210.4
A9: EPS (€) | B9: 3.62 | C9: 3.46 | D9: 5.43 | E9: 9.4 | F9: 11.2 | G9: 4.86 | H9: 5.68
A10: Dividend per share (€) | B10: 3.1 | C10: 3.1 | D10: 4.36 | E10: 7.5 | F10: 8.94 | H10: 4.3
A12: EBITDA margin | B12: =IF(B6="","",B6/B5) | C12: =IF(C6="","",C6/C5) -> 0.53075171 | D12: =IF(D6="","",D6/D5) -> 0.56394669 | E12: =IF(E6="","",E6/E5) -> 0.60508263 | F12: =IF(F6="","",F6/F5) -> 0.6747198 | G12: =IF(G6="","",G6/G5) -> 0.68047337 | H12: =IF(H6="","",H6/H5) -> 0.68060935
A13: EBIT margin | B13: =B7/B5 -> 0.52303781 | C13: =C7/C5 -> 0.49528148 | D13: =D7/D5 -> 0.54337152 | E13: =E7/E5 -> 0.5835672 | F13: =F7/F5 -> 0.64919054 | G13: =G7/G5 -> 0.66143555 | H13: =H7/H5 -> 0.64084689
A14: Payout (dividend / EPS) | B14: =IF(B10="","",B10/B9) -> 0.85635359 | C14: =IF(C10="","",C10/C9) -> 0.89595376 | D14: =IF(D10="","",D10/D9) -> 0.80294659 | E14: =IF(E10="","",E10/E9) -> 0.79787234 | F14: =IF(F10="","",F10/F9) -> 0.79821429 | G14: =IF(G10="","",G10/G9) | H14: =IF(H10="","",H10/H9) -> 0.75704225
A16: Order book (core business, excl. LNG as fuel)
B17: Units | C17: Revenue schedule (€mm)
A18: 31 Dec 2025 | B18: 288 | C18: 2026: 609 · 2027: 542 · 2028: 286 · 2029+: 155 (total 1,592)
A19: 30 Jun 2026 | B19: 306 | C19: H2-26: 300 · 2027: 655 · 2028: 603 · 2029+: 295 (total 1,853)
A20: Orders: 2022 peak 162 units; 2025: 45 (37 LNG carriers); H1 2026: 65 (56 LNG carriers)
A21: Company 10-year order estimate 2026-2035: c.550 LNG carriers, 25-40 ethane carriers, ≤10 FSRUs, ≤10 FLNGs, c.30 onshore tanks

Sheet DCF
A1: DCF by scenario (€mm). FY = calendar year. Cash flows 2027-2035 discounted from end-2026; H2 2026 cash flow added to net cash.
A3: Bear case
A4: €mm | C4: 2026 | D4: 2027 | E4: 2028 | F4: 2029 | G4: 2030 | H4: 2031 | I4: 2032 | J4: 2033 | K4: 2034 | L4: 2035
A5: Order-book revenue (already signed) | C5: =Inputs!C$41 -> 644.7 | D5: =Inputs!D$41 -> 655 | E5: =Inputs!E$41 -> 603 | F5: =Inputs!F$41 -> 221.3 | G5: =Inputs!G$41 -> 73.8 | H5: =Inputs!H$41 -> 0 | I5: =Inputs!I$41 -> 0 | J5: =Inputs!J$41 -> 0 | ... L5: =Inputs!L$41 -> 0
A6: New orders (units) | C6: =Inputs!C45 -> 15 | D6: =Inputs!D45 -> 35 | E6: =Inputs!E45 -> 35 | F6: =Inputs!F45 -> 35 | G6: =Inputs!G45 -> 35 | H6: =Inputs!H45 -> 35 | I6: =Inputs!I45 -> 35 | J6: =Inputs!J45 -> 35 | ... L6: =Inputs!L45 -> 35
A7: Royalty per unit | C7: =Inputs!$B$22*(1+Inputs!$B$23)^(2026-2026) -> 9.5 | D7: =Inputs!$B$22*(1+Inputs!$B$23)^(2027-2026) -> 9.69 | E7: =Inputs!$B$22*(1+Inputs!$B$23)^(2028-2026) -> 9.8838 | F7: =Inputs!$B$22*(1+Inputs!$B$23)^(2029-2026) -> 10.081476 | G7: =Inputs!$B$22*(1+Inputs!$B$23)^(2030-2026) -> 10.283106 | H7: =Inputs!$B$22*(1+Inputs!$B$23)^(2031-2026) -> 10.488768 | I7: =Inputs!$B$22*(1+Inputs!$B$23)^(2032-2026) -> 10.698543 | J7: =Inputs!$B$22*(1+Inputs!$B$23)^(2033-2026) -> 10.912514 | K7: =Inputs!$B$22*(1+Inputs!$B$23)^(2034-2026) -> 11.130764 | L7: =Inputs!$B$22*(1+Inputs!$B$23)^(2035-2026) -> 11.353379
A8: Value of new orders | C8: =C6*C7 -> 142.5 | D8: =D6*D7 -> 339.15 | E8: =E6*E7 -> 345.933 | F8: =F6*F7 -> 352.85166 | G8: =G6*G7 -> 359.90869 | H8: =H6*H7 -> 367.10687 | I8: =I6*I7 -> 374.449 | J8: =J6*J7 -> 381.93798 | ... L8: =L6*L7 -> 397.36828
A9: Revenue from new orders | C9: =0 -> 0 | D9: =C8*Inputs!$B$24 -> 28.5 | E9: =D8*Inputs!$B$24+C8*Inputs!$B$25 -> 146.205 | F9: =E8*Inputs!$B$24+D8*Inputs!$B$25+C8*Inputs!$B$26 -> 291.3441 | G9: =F8*Inputs!$B$24+E8*Inputs!$B$25+D8*Inputs!$B$26 -> 345.62098 | H9: =G8*Inputs!$B$24+F8*Inputs!$B$25+E8*Inputs!$B$26 -> 352.5334 | I9: =H8*Inputs!$B$24+G8*Inputs!$B$25+F8*Inputs!$B$26 -> 359.58407 | J9: =I8*Inputs!$B$24+H8*Inputs!$B$25+G8*Inputs!$B$26 -> 366.77575 | K9: =J8*Inputs!$B$24+I8*Inputs!$B$25+H8*Inputs!$B$26 -> 374.11127 | L9: =K8*Inputs!$B$24+J8*Inputs!$B$25+I8*Inputs!$B$26 -> 381.59349
A10: Core containment revenue | C10: =C5+C9 -> 644.7 | D10: =D5+D9 -> 683.5 | E10: =E5+E9 -> 749.205 | F10: =F5+F9 -> 512.6441 | G10: =G5+G9 -> 419.42098 | H10: =H5+H9 -> 352.5334 | I10: =I5+I9 -> 359.58407 | J10: =J5+J9 -> 366.77575 | ... L10: =L5+L9 -> 381.59349
A11: GTT Marine revenue | C11: =Inputs!$B$30 -> 70 | D11: =C11*(1+Inputs!$C$46) -> 72.1 | E11: =D11*(1+Inputs!$C$46) -> 74.263 | F11: =E11*(1+Inputs!$C$46) -> 76.49089 | G11: =F11*(1+Inputs!$C$46) -> 78.785617 | H11: =G11*(1+Inputs!$C$46) -> 81.149185 | I11: =H11*(1+Inputs!$C$46) -> 83.583661 | J11: =I11*(1+Inputs!$C$46) -> 86.091171 | K11: =J11*(1+Inputs!$C$46) -> 88.673906 | L11: =K11*(1+Inputs!$C$46) -> 91.334123
A12: Services and other | C12: =Inputs!$B$32*(1+Inputs!$B$33)^(2026-2026) -> 22 | D12: =Inputs!$B$32*(1+Inputs!$B$33)^(2027-2026) -> 22.44 | E12: =Inputs!$B$32*(1+Inputs!$B$33)^(2028-2026) -> 22.8888 | F12: =Inputs!$B$32*(1+Inputs!$B$33)^(2029-2026) -> 23.346576 | G12: =Inputs!$B$32*(1+Inputs!$B$33)^(2030-2026) -> 23.813508 | H12: =Inputs!$B$32*(1+Inputs!$B$33)^(2031-2026) -> 24.289778 | I12: =Inputs!$B$32*(1+Inputs!$B$33)^(2032-2026) -> 24.775573 | J12: =Inputs!$B$32*(1+Inputs!$B$33)^(2033-2026) -> 25.271085 | K12: =Inputs!$B$32*(1+Inputs!$B$33)^(2034-2026) -> 25.776506 | L12: =Inputs!$B$32*(1+Inputs!$B$33)^(2035-2026) -> 26.292037
A13: Total revenue | C13: =C10+C11+C12 -> 736.7 | D13: =D10+D11+D12 -> 778.04 | E13: =E10+E11+E12 -> 846.3568 | F13: =F10+F11+F12 -> 612.48157 | G13: =G10+G11+G12 -> 522.02011 | H13: =H10+H11+H12 -> 457.97236 | I13: =I10+I11+I12 -> 467.9433 | J13: =J10+J11+J12 -> 478.13801 | ... L13: =L10+L11+L12 -> 499.21965
A14: Core operating costs | C14: =-Inputs!$B$28*(1+Inputs!$B$29)^(2026-2026) -> -193 | D14: =-Inputs!$B$28*(1+Inputs!$B$29)^(2027-2026) -> -198.79 | E14: =-Inputs!$B$28*(1+Inputs!$B$29)^(2028-2026) -> -204.7537 | F14: =-Inputs!$B$28*(1+Inputs!$B$29)^(2029-2026) -> -210.89631 | G14: =-Inputs!$B$28*(1+Inputs!$B$29)^(2030-2026) -> -217.2232 | H14: =-Inputs!$B$28*(1+Inputs!$B$29)^(2031-2026) -> -223.7399 | I14: =-Inputs!$B$28*(1+Inputs!$B$29)^(2032-2026) -> -230.45209 | J14: =-Inputs!$B$28*(1+Inputs!$B$29)^(2033-2026) -> -237.36566 | K14: =-Inputs!$B$28*(1+Inputs!$B$29)^(2034-2026) -> -244.48663 | L14: =-Inputs!$B$28*(1+Inputs!$B$29)^(2035-2026) -> -251.82122
A15: GTT Marine costs | C15: =-C11*(1-Inputs!$B$31) -> -57.4 | D15: =-D11*(1-Inputs!$B$31) -> -59.122 | E15: =-E11*(1-Inputs!$B$31) -> -60.89566 | F15: =-F11*(1-Inputs!$B$31) -> -62.72253 | G15: =-G11*(1-Inputs!$B$31) -> -64.604206 | H15: =-H11*(1-Inputs!$B$31) -> -66.542332 | I15: =-I11*(1-Inputs!$B$31) -> -68.538602 | J15: =-J11*(1-Inputs!$B$31) -> -70.59476 | ... L15: =-L11*(1-Inputs!$B$31) -> -74.893981
A16: EBITDA | C16: =C13+C14+C15 -> 486.3 | D16: =D13+D14+D15 -> 520.128 | E16: =E13+E14+E15 -> 580.70744 | F16: =F13+F14+F15 -> 338.86273 | G16: =G13+G14+G15 -> 240.1927 | H16: =H13+H14+H15 -> 167.69014 | I16: =I13+I14+I15 -> 168.95261 | J16: =J13+J14+J15 -> 170.17759 | ... L16: =L13+L14+L15 -> 172.50445
A17: EBITDA margin | C17: =C16/C13 -> 0.66010588 | D17: =D16/D13 -> 0.66851062 | E17: =E16/E13 -> 0.68612604 | F17: =F16/F13 -> 0.55326192 | G17: =G16/G13 -> 0.46012155 | H17: =H16/H13 -> 0.36615776 | I17: =I16/I13 -> 0.36105359 | J17: =J16/J13 -> 0.3559173 | ... L17: =L16/L13 -> 0.34554819
A18: D&A | C18: =-Inputs!$B$34 -> -30 | D18: =-Inputs!$B$34 -> -30 | E18: =-Inputs!$B$34 -> -30 | F18: =-Inputs!$B$34 -> -30 | G18: =-Inputs!$B$34 -> -30 | H18: =-Inputs!$B$34 -> -30 | I18: =-Inputs!$B$34 -> -30 | J18: =-Inputs!$B$34 -> -30 | ... L18: =-Inputs!$B$34 -> -30
A19: EBIT | C19: =C16+C18 -> 456.3 | D19: =D16+D18 -> 490.128 | E19: =E16+E18 -> 550.70744 | F19: =F16+F18 -> 308.86273 | G19: =G16+G18 -> 210.1927 | H19: =H16+H18 -> 137.69014 | I19: =I16+I18 -> 138.95261 | J19: =J16+J18 -> 140.17759 | ... L19: =L16+L18 -> 142.50445
A20: Taxes | C20: =-C19*Inputs!$B$17 -> -73.008 | D20: =-D19*Inputs!$B$17 -> -78.42048 | E20: =-E19*Inputs!$B$17 -> -88.11319 | F20: =-F19*Inputs!$B$17 -> -49.418036 | G20: =-G19*Inputs!$B$17 -> -33.630832 | H20: =-H19*Inputs!$B$17 -> -22.030422 | I20: =-I19*Inputs!$B$17 -> -22.232417 | J20: =-J19*Inputs!$B$17 -> -22.428414 | ... L20: =-L19*Inputs!$B$17 -> -22.800711
A21: NOPAT | C21: =C19+C20 -> 383.292 | D21: =D19+D20 -> 411.70752 | E21: =E19+E20 -> 462.59425 | F21: =F19+F20 -> 259.44469 | G21: =G19+G20 -> 176.56187 | H21: =H19+H20 -> 115.65971 | I21: =I19+I20 -> 116.72019 | J21: =J19+J20 -> 117.74918 | ... L21: =L19+L20 -> 119.70373
A22: Capex | C22: =-Inputs!$B$35 -> -30 | D22: =-Inputs!$B$35 -> -30 | E22: =-Inputs!$B$35 -> -30 | F22: =-Inputs!$B$35 -> -30 | G22: =-Inputs!$B$35 -> -30 | H22: =-Inputs!$B$35 -> -30 | I22: =-Inputs!$B$35 -> -30 | J22: =-Inputs!$B$35 -> -30 | ... L22: =-Inputs!$B$35 -> -30
A23: Change in NWC | C23: =0 -> 0 | D23: =-Inputs!$B$36*(D13-C13) -> -4.134 | E23: =-Inputs!$B$36*(E13-D13) -> -6.83168 | F23: =-Inputs!$B$36*(F13-E13) -> 23.387523 | G23: =-Inputs!$B$36*(G13-F13) -> 9.046146 | H23: =-Inputs!$B$36*(H13-G13) -> 6.4047742 | I23: =-Inputs!$B$36*(I13-H13) -> -0.99709391 | J23: =-Inputs!$B$36*(J13-I13) -> -1.0194703 | K23: =-Inputs!$B$36*(K13-J13) -> -1.0423672 | L23: =-Inputs!$B$36*(L13-K13) -> -1.0657973
A24: Free cash flow | C24: =C21-C18+C22+C23 -> 383.292 | D24: =D21-D18+D22+D23 -> 407.57352 | E24: =E21-E18+E22+E23 -> 455.76257 | F24: =F21-F18+F22+F23 -> 282.83221 | G24: =G21-G18+G22+G23 -> 185.60801 | H24: =H21-H18+H22+H23 -> 122.06449 | I24: =I21-I18+I22+I23 -> 115.7231 | J24: =J21-J18+J22+J23 -> 116.72971 | ... L24: =L21-L18+L22+L23 -> 118.63794
A25: Discount period (years) | D25: 1 | E25: 2 | F25: 3 | G25: 4 | H25: 5 | I25: 6 | J25: 7 | K25: 8 | L25: 9
A26: Discount factor | D26: =1/(1+Inputs!$B$19)^D25 -> 0.91217509 | E26: =1/(1+Inputs!$B$19)^E25 -> 0.83206339 | F26: =1/(1+Inputs!$B$19)^F25 -> 0.7589875 | G26: =1/(1+Inputs!$B$19)^G25 -> 0.69232949 | H26: =1/(1+Inputs!$B$19)^H25 -> 0.63152571 | I26: =1/(1+Inputs!$B$19)^I25 -> 0.57606202 | J26: =1/(1+Inputs!$B$19)^J25 -> 0.52546943 | K26: =1/(1+Inputs!$B$19)^K25 -> 0.47932012 | L26: =1/(1+Inputs!$B$19)^L25 -> 0.43722388
A27: PV of FCF | D27: =D24*D26 -> 371.77841 | E27: =E24*E26 -> 379.22335 | F27: =F24*F26 -> 214.66611 | G27: =G24*G26 -> 128.5019 | H27: =H24*H26 -> 77.086863 | I27: =I24*I26 -> 66.663682 | J27: =J24*J26 -> 61.337892 | K27: =K24*K26 -> 56.41698 | L27: =L24*L26 -> 51.871339
A29: Terminal growth | C29: =Inputs!C47 -> 0
A30: Terminal value at 2035 | C30: =L24*(1+C29)/(Inputs!$B$19-C29) -> 1232.2081
A31: PV of terminal value | C31: =C30*L26 -> 538.75082
A32: Sum of PV of FCF (2027-35) | C32: =SUM(D27:L27) -> 1407.5465
A33: Enterprise value | C33: =C31+C32 -> 1946.2974
A34: + Net cash at 30 June 2026 | C34: =Inputs!$B$9 -> 294.7
A35: + H2 2026 free cash flow | C35: =C24*Inputs!$B$37 -> 191.646
A36: Equity value | C36: =SUM(C33:C35) -> 2432.6434
A37: Value per share (€) | C37: =C36/Inputs!$B$6 -> 65.628277
A38: Upside / (downside) vs price | C38: =C37/Inputs!$B$5-1 -> -0.68984746
A39: Terminal value as % of EV | C39: =C31/C33 -> 0.27680807
A40: Implied P/E on 2027 NOPAT | C40: =Inputs!$B$18/D21 -> 19.050848
A41: Average new orders 2027-35 (units/yr) | C41: =AVERAGE(D6:L6) -> 35
A44: Base case
...

Sheet Reverse DCF
A1: What do you have to believe? Orders a year (LNG-carrier equivalents, 2027-35) that justify the price; everything else as in the base case.
A2: Value is linear in orders, so it is solved exactly from two helper DCFs (0 and 1 order a year).
A4: Target equity value (price x shares) | C4: =Inputs!B18 -> 7843.3772
A5: Equity value with 0 orders a year | C5: =DCF!C161 -> -252.42662
A6: Extra equity value per order a year | C6: =DCF!C202-DCF!C161 -> 84.088732
A7: Implied orders a year, 2027-2035 | C7: =(C4-C5)/C6 -> 96.276916
A8: Base case assumption | C8: =Inputs!D50 -> 60
A9: Company 10-year estimate (c.550 LNGC + other units, per year) | C9: 60
A12: Free cash flow rows used by the grid (€mm)
C13: 2027 | D13: 2028 | E13: 2029 | F13: 2030 | G13: 2031 | H13: 2032 | I13: 2033 | J13: 2034 | K13: 2035
A14: F0: FCF with 0 orders a year | C14: =DCF!D149 -> 428.84272 | D14: =DCF!E149 -> 467.14398 | E14: =DCF!F149 -> 122.35405 | F14: =DCF!G149 -> -90.149859 | G14: =DCF!H149 -> -170.61623 | H14: =DCF!I149 -> -182.0442 | I14: =DCF!J149 -> -186.15852 | J14: =DCF!K149 -> -190.33654 | K14: =DCF!L149 -> -194.57513
A15: dF: FCF per order a year | C15: =DCF!D190-DCF!D149 -> 0 | D15: =DCF!E190-DCF!E149 -> 1.43412 | E15: =DCF!F190-DCF!F149 -> 5.6004324 | F15: =DCF!G190-DCF!G149 -> 8.038041 | G15: =DCF!H190-DCF!H149 -> 8.4410519 | H15: =DCF!I190-DCF!I149 -> 8.6098729 | I15: =DCF!J190-DCF!J149 -> 8.7820704 | J15: =DCF!K190-DCF!K149 -> 8.9577118 | K15: =DCF!L190-DCF!L149 -> 9.136866
A16: Discount period | C16: 1 | D16: 2 | E16: 3 | F16: 4 | G16: 5 | H16: 6 | I16: 7 | J16: 8 | K16: 9
A19: Value per share (€): WACC (rows) x new orders a year 2027-35 (columns)
A20: WACC \ orders | C20: 30 | D20: 40 | E20: 50 | F20: 60 | G20: 70 | H20: 80 | I20: 90
A21: 0.075 | C21: =(SUMPRODUCT(($C$14:$K$14+C$20*$C$15:$K$15)/(1+$A21)^$C$16:$K$16)+($K$14+C$20*$K$15)*(1+Inputs!$C$52)/($A21-Inputs!$C$52)/(1+$A21)^$K$16+(Inputs!$B$9+DCF!C160))/Inputs!$B$6 -> 70.527837 | D21: =(SUMPRODUCT(($C$14:$K$14+D$20*$C$15:$K$15)/(1+$A21)^$C$16:$K$16)+($K$14+D$20*$K$15)*(1+Inputs!$C$52)/($A21-Inputs!$C$52)/(1+$A21)^$K$16+(Inputs!$B$9+DCF!C160))/Inputs!$B$6 -> 102.61216 | E21: =(SUMPRODUCT(($C$14:$K$14+E$20*$C$15:$K$15)/(1+$A21)^$C$16:$K$16)+($K$14+E$20*$K$15)*(1+Inputs!$C$52)/($A21-Inputs!$C$52)/(1+$A21)^$K$16+(Inputs!$B$9+DCF!C160))/Inputs!$B$6 -> 134.69648 | F21: =(SUMPRODUCT(($C$14:$K$14+F$20*$C$15:$K$15)/(1+$A21)^$C$16:$K$16)+($K$14+F$20*$K$15)*(1+Inputs!$C$52)/($A21-Inputs!$C$52)/(1+$A21)^$K$16+(Inputs!$B$9+DCF!C160))/Inputs!$B$6 -> 166.78081 | G21: =(SUMPRODUCT(($C$14:$K$14+G$20*$C$15:$K$15)/(1+$A21)^$C$16:$K$16)+($K$14+G$20*$K$15)*(1+Inputs!$C$52)/($A21-Inputs!$C$52)/(1+$A21)^$K$16+(Inputs!$B$9+DCF!C160))/Inputs!$B$6 -> 198.86513 | H21: =(SUMPRODUCT(($C$14:$K$14+H$20*$C$15:$K$15)/(1+$A21)^$C$16:$K$16)+($K$14+H$20*$K$15)*(1+Inputs!$C$52)/($A21-Inputs!$C$52)/(1+$A21)^$K$16+(Inputs!$B$9+DCF!C160))/Inputs!$B$6 -> 230.94945 | I21: =(SUMPRODUCT(($C$14:$K$14+I$20*$C$15:$K$15)/(1+$A21)^$C$16:$K$16)+($K$14+I$20*$K$15)*(1+Inputs!$C$52)/($A21-Inputs!$C$52)/(1+$A21)^$K$16+(Inputs!$B$9+DCF!C160))/Inputs!$B$6 -> 263.03377
A22: 0.08 | C22: =(SUMPRODUCT(($C$14:$K$14+C$20*$C$15:$K$15)/(1+$A22)^$C$16:$K$16)+($K$14+C$20*$K$15)*(1+Inputs!$C$52)/($A22-Inputs!$C$52)/(1+$A22)^$K$16+(Inputs!$B$9+DCF!C160))/Inputs!$B$6 -> 67.852274 | D22: =(SUMPRODUCT(($C$14:$K$14+D$20*$C$15:$K$15)/(1+$A22)^$C$16:$K$16)+($K$14+D$20*$K$15)*(1+Inputs!$C$52)/($A22-Inputs!$C$52)/(1+$A22)^$K$16+(Inputs!$B$9+DCF!C160))/Inputs!$B$6 -> 97.167283 | E22: =(SUMPRODUCT(($C$14:$K$14+E$20*$C$15:$K$15)/(1+$A22)^$C$16:$K$16)+($K$14+E$20*$K$15)*(1+Inputs!$C$52)/($A22-Inputs!$C$52)/(1+$A22)^$K$16+(Inputs!$B$9+DCF!C160))/Inputs!$B$6 -> 126.48229 | F22: =(SUMPRODUCT(($C$14:$K$14+F$20*$C$15:$K$15)/(1+$A22)^$C$16:$K$16)+($K$14+F$20*$K$15)*(1+Inputs!$C$52)/($A22-Inputs!$C$52)/(1+$A22)^$K$16+(Inputs!$B$9+DCF!C160))/Inputs!$B$6 -> 155.7973 | G22: =(SUMPRODUCT(($C$14:$K$14+G$20*$C$15:$K$15)/(1+$A22)^$C$16:$K$16)+($K$14+G$20*$K$15)*(1+Inputs!$C$52)/($A22-Inputs!$C$52)/(1+$A22)^$K$16+(Inputs!$B$9+DCF!C160))/Inputs!$B$6 -> 185.11231 | H22: =(SUMPRODUCT(($C$14:$K$14+H$20*$C$15:$K$15)/(1+$A22)^$C$16:$K$16)+($K$14+H$20*$K$15)*(1+Inputs!$C$52)/($A22-Inputs!$C$52)/(1+$A22)^$K$16+(Inputs!$B$9+DCF!C160))/Inputs!$B$6 -> 214.42732 | I22: =(SUMPRODUCT(($C$14:$K$14+I$20*$C$15:$K$15)/(1+$A22)^$C$16:$K$16)+($K$14+I$20*$K$15)*(1+Inputs!$C$52)/($A22-Inputs!$C$52)/(1+$A22)^$K$16+(Inputs!$B$9+DCF!C160))/Inputs!$B$6 -> 243.74233
A23: 0.085 | C23: =(SUMPRODUCT(($C$14:$K$14+C$20*$C$15:$K$15)/(1+$A23)^$C$16:$K$16)+($K$14+C$20*$K$15)*(1+Inputs!$C$52)/($A23-Inputs!$C$52)/(1+$A23)^$K$16+(Inputs!$B$9+DCF!C160))/Inputs!$B$6 -> 65.529192 | D23: =(SUMPRODUCT(($C$14:$K$14+D$20*$C$15:$K$15)/(1+$A23)^$C$16:$K$16)+($K$14+D$20*$K$15)*(1+Inputs!$C$52)/($A23-Inputs!$C$52)/(1+$A23)^$K$16+(Inputs!$B$9+DCF!C160))/Inputs!$B$6 -> 92.475107 | E23: =(SUMPRODUCT(($C$14:$K$14+E$20*$C$15:$K$15)/(1+$A23)^$C$16:$K$16)+($K$14+E$20*$K$15)*(1+Inputs!$C$52)/($A23-Inputs!$C$52)/(1+$A23)^$K$16+(Inputs!$B$9+DCF!C160))/Inputs!$B$6 -> 119.42102 | F23: =(SUMPRODUCT(($C$14:$K$14+F$20*$C$15:$K$15)/(1+$A23)^$C$16:$K$16)+($K$14+F$20*$K$15)*(1+Inputs!$C$52)/($A23-Inputs!$C$52)/(1+$A23)^$K$16+(Inputs!$B$9+DCF!C160))/Inputs!$B$6 -> 146.36694 | G23: =(SUMPRODUCT(($C$14:$K$14+G$20*$C$15:$K$15)/(1+$A23)^$C$16:$K$16)+($K$14+G$20*$K$15)*(1+Inputs!$C$52)/($A23-Inputs!$C$52)/(1+$A23)^$K$16+(Inputs!$B$9+DCF!C160))/Inputs!$B$6 -> 173.31285 | H23: =(SUMPRODUCT(($C$14:$K$14+H$20*$C$15:$K$15)/(1+$A23)^$C$16:$K$16)+($K$14+H$20*$K$15)*(1+Inputs!$C$52)/($A23-Inputs!$C$52)/(1+$A23)^$K$16+(Inputs!$B$9+DCF!C160))/Inputs!$B$6 -> 200.25877 | I23: =(SUMPRODUCT(($C$14:$K$14+I$20*$C$15:$K$15)/(1+$A23)^$C$16:$K$16)+($K$14+I$20*$K$15)*(1+Inputs!$C$52)/($A23-Inputs!$C$52)/(1+$A23)^$K$16+(Inputs!$B$9+DCF!C160))/Inputs!$B$6 -> 227.20468
A24: 0.09 | C24: =(SUMPRODUCT(($C$14:$K$14+C$20*$C$15:$K$15)/(1+$A24)^$C$16:$K$16)+($K$14+C$20*$K$15)*(1+Inputs!$C$52)/($A24-Inputs!$C$52)/(1+$A24)^$K$16+(Inputs!$B$9+DCF!C160))/Inputs!$B$6 -> 63.488743 | D24: =(SUMPRODUCT(($C$14:$K$14+D$20*$C$15:$K$15)/(1+$A24)^$C$16:$K$16)+($K$14+D$20*$K$15)*(1+Inputs!$C$52)/($A24-Inputs!$C$52)/(1+$A24)^$K$16+(Inputs!$B$9+DCF!C160))/Inputs!$B$6 -> 88.385643 | E24: =(SUMPRODUCT(($C$14:$K$14+E$20*$C$15:$K$15)/(1+$A24)^$C$16:$K$16)+($K$14+E$20*$K$15)*(1+Inputs!$C$52)/($A24-Inputs!$C$52)/(1+$A24)^$K$16+(Inputs!$B$9+DCF!C160))/Inputs!$B$6 -> 113.28254 | F24: =(SUMPRODUCT(($C$14:$K$14+F$20*$C$15:$K$15)/(1+$A24)^$C$16:$K$16)+($K$14+F$20*$K$15)*(1+Inputs!$C$52)/($A24-Inputs!$C$52)/(1+$A24)^$K$16+(Inputs!$B$9+DCF!C160))/Inputs!$B$6 -> 138.17944 | G24: =(SUMPRODUCT(($C$14:$K$14+G$20*$C$15:$K$15)/(1+$A24)^$C$16:$K$16)+($K$14+G$20*$K$15)*(1+Inputs!$C$52)/($A24-Inputs!$C$52)/(1+$A24)^$K$16+(Inputs!$B$9+DCF!C160))/Inputs!$B$6 -> 163.07634 | H24: =(SUMPRODUCT(($C$14:$K$14+H$20*$C$15:$K$15)/(1+$A24)^$C$16:$K$16)+($K$14+H$20*$K$15)*(1+Inputs!$C$52)/($A24-Inputs!$C$52)/(1+$A24)^$K$16+(Inputs!$B$9+DCF!C160))/Inputs!$B$6 -> 187.97324 | I24: =(SUMPRODUCT(($C$14:$K$14+I$20*$C$15:$K$15)/(1+$A24)^$C$16:$K$16)+($K$14+I$20*$K$15)*(1+Inputs!$C$52)/($A24-Inputs!$C$52)/(1+$A24)^$K$16+(Inputs!$B$9+DCF!C160))/Inputs!$B$6 -> 212.87014
A25: 0.095 | C25: =(SUMPRODUCT(($C$14:$K$14+C$20*$C$15:$K$15)/(1+$A25)^$C$16:$K$16)+($K$14+C$20*$K$15)*(1+Inputs!$C$52)/($A25-Inputs!$C$52)/(1+$A25)^$K$16+(Inputs!$B$9+DCF!C160))/Inputs!$B$6 -> 61.678528 | D25: =(SUMPRODUCT(($C$14:$K$14+D$20*$C$15:$K$15)/(1+$A25)^$C$16:$K$16)+($K$14+D$20*$K$15)*(1+Inputs!$C$52)/($A25-Inputs!$C$52)/(1+$A25)^$K$16+(Inputs!$B$9+DCF!C160))/Inputs!$B$6 -> 84.786388 | E25: =(SUMPRODUCT(($C$14:$K$14+E$20*$C$15:$K$15)/(1+$A25)^$C$16:$K$16)+($K$14+E$20*$K$15)*(1+Inputs!$C$52)/($A25-Inputs!$C$52)/(1+$A25)^$K$16+(Inputs!$B$9+DCF!C160))/Inputs!$B$6 -> 107.89425 | F25: =(SUMPRODUCT(($C$14:$K$14+F$20*$C$15:$K$15)/(1+$A25)^$C$16:$K$16)+($K$14+F$20*$K$15)*(1+Inputs!$C$52)/($A25-Inputs!$C$52)/(1+$A25)^$K$16+(Inputs!$B$9+DCF!C160))/Inputs!$B$6 -> 131.00211 | G25: =(SUMPRODUCT(($C$14:$K$14+G$20*$C$15:$K$15)/(1+$A25)^$C$16:$K$16)+($K$14+G$20*$K$15)*(1+Inputs!$C$52)/($A25-Inputs!$C$52)/(1+$A25)^$K$16+(Inputs!$B$9+DCF!C160))/Inputs!$B$6 -> 154.10997 | H25: =(SUMPRODUCT(($C$14:$K$14+H$20*$C$15:$K$15)/(1+$A25)^$C$16:$K$16)+($K$14+H$20*$K$15)*(1+Inputs!$C$52)/($A25-Inputs!$C$52)/(1+$A25)^$K$16+(Inputs!$B$9+DCF!C160))/Inputs!$B$6 -> 177.21783 | I25: =(SUMPRODUCT(($C$14:$K$14+I$20*$C$15:$K$15)/(1+$A25)^$C$16:$K$16)+($K$14+I$20*$K$15)*(1+Inputs!$C$52)/($A25-Inputs!$C$52)/(1+$A25)^$K$16+(Inputs!$B$9+DCF!C160))/Inputs!$B$6 -> 200.32569
A26: 0.1 | C26: =(SUMPRODUCT(($C$14:$K$14+C$20*$C$15:$K$15)/(1+$A26)^$C$16:$K$16)+($K$14+C$20*$K$15)*(1+Inputs!$C$52)/($A26-Inputs!$C$52)/(1+$A26)^$K$16+(Inputs!$B$9+DCF!C160))/Inputs!$B$6 -> 60.058457 | D26: =(SUMPRODUCT(($C$14:$K$14+D$20*$C$15:$K$15)/(1+$A26)^$C$16:$K$16)+($K$14+D$20*$K$15)*(1+Inputs!$C$52)/($A26-Inputs!$C$52)/(1+$A26)^$K$16+(Inputs!$B$9+DCF!C160))/Inputs!$B$6 -> 81.591296 | E26: =(SUMPRODUCT(($C$14:$K$14+E$20*$C$15:$K$15)/(1+$A26)^$C$16:$K$16)+($K$14+E$20*$K$15)*(1+Inputs!$C$52)/($A26-Inputs!$C$52)/(1+$A26)^$K$16+(Inputs!$B$9+DCF!C160))/Inputs!$B$6 -> 103.12413 | F26: =(SUMPRODUCT(($C$14:$K$14+F$20*$C$15:$K$15)/(1+$A26)^$C$16:$K$16)+($K$14+F$20*$K$15)*(1+Inputs!$C$52)/($A26-Inputs!$C$52)/(1+$A26)^$K$16+(Inputs!$B$9+DCF!C160))/Inputs!$B$6 -> 124.65697 | G26: =(SUMPRODUCT(($C$14:$K$14+G$20*$C$15:$K$15)/(1+$A26)^$C$16:$K$16)+($K$14+G$20*$K$15)*(1+Inputs!$C$52)/($A26-Inputs!$C$52)/(1+$A26)^$K$16+(Inputs!$B$9+DCF!C160))/Inputs!$B$6 -> 146.18981 | H26: =(SUMPRODUCT(($C$14:$K$14+H$20*$C$15:$K$15)/(1+$A26)^$C$16:$K$16)+($K$14+H$20*$K$15)*(1+Inputs!$C$52)/($A26-Inputs!$C$52)/(1+$A26)^$K$16+(Inputs!$B$9+DCF!C160))/Inputs!$B$6 -> 167.72265 | I26: =(SUMPRODUCT(($C$14:$K$14+I$20*$C$15:$K$15)/(1+$A26)^$C$16:$K$16)+($K$14+I$20*$K$15)*(1+Inputs!$C$52)/($A26-Inputs!$C$52)/(1+$A26)^$K$16+(Inputs!$B$9+DCF!C160))/Inputs!$B$6 -> 189.25549
A27: 0.11 | C27: =(SUMPRODUCT(($C$14:$K$14+C$20*$C$15:$K$15)/(1+$A27)^$C$16:$K$16)+($K$14+C$20*$K$15)*(1+Inputs!$C$52)/($A27-Inputs!$C$52)/(1+$A27)^$K$16+(Inputs!$B$9+DCF!C160))/Inputs!$B$6 -> 57.270532 | D27: =(SUMPRODUCT(($C$14:$K$14+D$20*$C$15:$K$15)/(1+$A27)^$C$16:$K$16)+($K$14+D$20*$K$15)*(1+Inputs!$C$52)/($A27-Inputs!$C$52)/(1+$A27)^$K$16+(Inputs!$B$9+DCF!C160))/Inputs!$B$6 -> 76.159929 | E27: =(SUMPRODUCT(($C$14:$K$14+E$20*$C$15:$K$15)/(1+$A27)^$C$16:$K$16)+($K$14+E$20*$K$15)*(1+Inputs!$C$52)/($A27-Inputs!$C$52)/(1+$A27)^$K$16+(Inputs!$B$9+DCF!C160))/Inputs!$B$6 -> 95.049327 | F27: =(SUMPRODUCT(($C$14:$K$14+F$20*$C$15:$K$15)/(1+$A27)^$C$16:$K$16)+($K$14+F$20*$K$15)*(1+Inputs!$C$52)/($A27-Inputs!$C$52)/(1+$A27)^$K$16+(Inputs!$B$9+DCF!C160))/Inputs!$B$6 -> 113.93872 | G27: =(SUMPRODUCT(($C$14:$K$14+G$20*$C$15:$K$15)/(1+$A27)^$C$16:$K$16)+($K$14+G$20*$K$15)*(1+Inputs!$C$52)/($A27-Inputs!$C$52)/(1+$A27)^$K$16+(Inputs!$B$9+DCF!C160))/Inputs!$B$6 -> 132.82812 | H27: =(SUMPRODUCT(($C$14:$K$14+H$20*$C$15:$K$15)/(1+$A27)^$C$16:$K$16)+($K$14+H$20*$K$15)*(1+Inputs!$C$52)/($A27-Inputs!$C$52)/(1+$A27)^$K$16+(Inputs!$B$9+DCF!C160))/Inputs!$B$6 -> 151.71752 | I27: =(SUMPRODUCT(($C$14:$K$14+I$20*$C$15:$K$15)/(1+$A27)^$C$16:$K$16)+($K$14+I$20*$K$15)*(1+Inputs!$C$52)/($A27-Inputs!$C$52)/(1+$A27)^$K$16+(Inputs!$B$9+DCF!C160))/Inputs!$B$6 -> 170.60692
A29: Current price (€) | C29: =Inputs!B5 -> 211.6
A30: Model WACC | C30: =Inputs!B19 -> 0.09628076
