Workbook

Sheet Summary
A1: JPMorgan Chase (JPM): three-scenario residual income model
A2: Valuation date 2026-10-16. $mm unless stated. Change blue/yellow cells in 'Inputs'; everything else recalculates.
B4: Bear | C4: Base | D4: Bull | E4: Prob.-weighted
A5: ROTE in Y2 | B5: ='RI model'!E5 -> 0.12 | C5: ='RI model'!E30 -> 0.19 | D5: ='RI model'!E64 -> 0.21
A6: Long-run ROTE | B6: ='RI model'!C15 -> 0.15 | C6: ='RI model'!C40 -> 0.17 | D6: ='RI model'!C74 -> 0.2
A7: Equity value | B7: ='RI model'!C21 -> 602533.29 | C7: ='RI model'!C46 -> 731645.11 | D7: ='RI model'!C80 -> 915028.88
A8: Value per share ($) | B8: ='RI model'!C22 -> 227.23818 | C8: ='RI model'!C47 -> 275.93115 | D8: ='RI model'!C81 -> 345.09214 | E8: =SUMPRODUCT(B8:D8,B11:D11) -> 281.04815
A9: Upside / (downside) | B9: ='RI model'!C23 -> -0.33110155 | C9: ='RI model'!C48 -> -0.1877689 | D9: ='RI model'!C82 -> 0.015813421 | E9: =E8/Inputs!B5-1 -> -0.17270648
A10: Implied P/TBV | B10: ='RI model'!C24 -> 2.0173844 | C10: ='RI model'!C49 -> 2.4496729 | D10: ='RI model'!C83 -> 3.0636731
A11: Probability | B11: =Inputs!B46 -> 0.25 | C11: =Inputs!B47 -> 0.5 | D11: =Inputs!B48 -> 0.25
A13: Current price ($) / P/TBV | B13: =Inputs!B5 -> 339.72 | C13: =Inputs!B12 -> 3.0159801
A14: Cost of equity / terminal growth | B14: =Inputs!B21 -> 0.1015025 | C14: =Inputs!B22 -> 0.04
A15: ROTE the price implies, forever | B15: =Reverse!C6 -> 0.22549032
A16: Analyst mean target ($) | B16: =Inputs!B52 -> 372.57
A18: Legend: blue = input, black = formula, green = link to another sheet, yellow = key assumption.
A19: Sources: JPM Q3 2026 earnings release (2026-10-13); SEC EDGAR XBRL; Yahoo Finance 2026-10-16.
A20: Personal research, not investment advice.

Sheet Inputs
A1: JPMorgan Chase: inputs and scenario levers ($mm unless stated)
A2: Blue = hardcoded input. Yellow = key assumption. Black = formula. Sources in column O.
A4: Market data and capital
A5: Share price ($) | B5: 339.72 | O5: Yahoo Finance, close 2026-10-16
A6: Common shares outstanding (mm) | B6: =(B7-B8)/B9 -> 2651.5495 | O6: Derived: (total equity - preferred) / book value per share; Yahoo shows 2,655.6mm
A7: Total stockholders' equity, 30 Sep 2026 | B7: 372000 | O7: Q3 2026 earnings release (8-K exhibit 99.1, 2026-10-13)
A8: Preferred stock (liquidation preference) | B8: 21200 | O8: SEC XBRL PreferredStockLiquidationPreferenceValue, 30 Jun 2026
A9: Book value per share ($) | B9: 132.3 | O9: Q3 2026 earnings release
A10: Tangible book value per share ($) | B10: 112.64 | O10: Q3 2026 earnings release
A11: Tangible common equity (TCE) | B11: =B10*B6 -> 298670.54 | O11: Formula
A12: Current P/TBV | B12: =B5/B10 -> 3.0159801 | O12: Formula
A13: Q3 2026 ROTCE: reported / ex significant items | B13: 20% / 21% | O13: Q3 2026 earnings release ($658mm securities loss)
A14: CET1 ratio (Standardized) | B14: 0.139 | O14: Q3 2026 earnings release; ~$30bn excess capital per management
A16: Cost of equity
A17: Risk-free rate (US 10-year) | B17: 0.051 | O17: ^TNX close 2026-10-16
A18: Beta (5y monthly) | B18: 1.015 | O18: Yahoo Finance
A19: Adjusted beta (Blume: 0.67 x raw + 0.33) | B19: =0.67*B18+0.33 -> 1.01005 | O19: Formula
A20: Equity risk premium | B20: 0.05 | O20: Assumption (author)
A21: Cost of equity (r) | B21: =B17+B19*B20 -> 0.1015025 | O21: CAPM
A22: Terminal growth (g) | B22: 0.04 | O22: Assumption: roughly US nominal GDP; same as the original pitch
A24: Per-share mechanics (illustrative block in the base case)
A25: Share of distributions done as buybacks | B25: 0.5 | O25: Assumption; Q3 2026 net buybacks $0.66bn vs dividends $4.4bn
A26: Buyback price as a multiple of TBVPS | B26: =B12 -> 3.0159801 | O26: Assumes today's P/TBV persists
A28: Scenarios: return on tangible common equity by year (Y1 = Oct 2026 - Sep 2027)
D29: Y1 | E29: Y2 | F29: Y3 | G29: Y4 | H29: Y5 | I29: Y6 | J29: Y7 | K29: Y8 | L29: Y9 | M29: Y10
A30: Bear case | O30: Credit cycle in 2027-28 (card and wholesale losses, reserve builds), then a lower-return normal of 15%.
A31: ROTE | D31: 0.19 | E31: 0.12 | F31: 0.11 | G31: 0.14 | H31: 0.15 | I31: 0.15 | J31: 0.15 | K31: 0.15 | L31: 0.15 | M31: 0.15
A32: Long-run ROTE (terminal) | C32: 0.15
A33: Payout (dividends + buybacks, % of earnings) | C33: 0.45
A35: Base case | O35: Glide from today's ~21% core ROTCE to management's through-the-cycle target of 17%.
A36: ROTE | D36: 0.2 | E36: 0.19 | F36: 0.18 | G36: 0.175 | H36: 0.17 | I36: 0.17 | J36: 0.17 | K36: 0.17 | L36: 0.17 | M36: 0.17 | O36: Management's through-the-cycle ROTCE target is 17%; Q3 2026 core ROTCE was 21%.
A37: Long-run ROTE (terminal) | C37: 0.17
A38: Payout (dividends + buybacks, % of earnings) | C38: 0.6
A40: Bull case | O40: JPM keeps its edge: ROTE stays above 20% for a decade.
A41: ROTE | D41: 0.21 | E41: 0.21 | F41: 0.21 | G41: 0.21 | H41: 0.21 | I41: 0.205 | J41: 0.2 | K41: 0.2 | L41: 0.2 | M41: 0.2
A42: Long-run ROTE (terminal) | C42: 0.2
A43: Payout (dividends + buybacks, % of earnings) | C43: 0.65
A45: Scenario probabilities
A46: Bear | B46: 0.25
A47: Base | B47: 0.5
...

Sheet Historical
A1: JPMorgan Chase: history ($mm unless stated)
A2: Source: SEC EDGAR XBRL company facts (10-K), CIK 0000019617.
A4: $mm | B4: 2012 | C4: 2013 | D4: 2014 | E4: 2015 | F4: 2016 | G4: 2017 | H4: 2018 | I4: 2019 | J4: 2020 | K4: 2021 | L4: 2022 | M4: 2023 | N4: 2024 | O4: 2025
A5: Net interest income | B5: 44910 | C5: 43319 | D5: 43634 | E5: 43510 | F5: 46083 | G5: 50097 | H5: 55059 | I5: 57245 | J5: 54563 | K5: 52311 | L5: 66710 | M5: 89267 | N5: 92583 | O5: 95443
A6: Noninterest revenue | B6: 52121 | C6: 54048 | D6: 51478 | E6: 50033 | F6: 50486 | G6: 50608 | H6: 53724 | I6: 58475 | J6: 65388 | K6: 69338 | L6: 61985 | M6: 68837 | N6: 84973 | O6: 87004
A7: Noninterest expense | B7: 64729 | C7: 70467 | D7: 61274 | E7: 59014 | F7: 56672 | G7: 59515 | H7: 63148 | I7: 65269 | J7: 66656 | K7: 71343 | L7: 76140 | M7: 87172 | N7: 91797 | O7: 95640
A8: Provision for credit losses | B8: 3385 | C8: 225 | D8: 3139 | E8: 3827 | F8: 5361 | G8: 5290 | H8: 4871 | I8: 5585 | J8: 17480 | K8: -9256 | L8: 6389 | M8: 9320 | N8: 10678 | O8: 14212
A9: Net income | B9: 21284 | C9: 17886 | D9: 21745 | E9: 24442 | F9: 24733 | G9: 24441 | H9: 32474 | I9: 36431 | J9: 29131 | K9: 48334 | L9: 37676 | M9: 49552 | N9: 58471 | O9: 57048
A10: Net income to common | B10: 19877 | C10: 16557 | D10: 20077 | E10: 22651 | F10: 22834 | G10: 22567 | H10: 30709 | I10: 34642 | J10: 27410 | K10: 46503 | L10: 35892 | M10: 47760 | N10: 56868 | O10: 55681
A11: Total stockholders' equity | B11: 204069 | C11: 211178 | D11: 231727 | E11: 247573 | F11: 254190 | G11: 255693 | H11: 256515 | I11: 261330 | J11: 279354 | K11: 294127 | L11: 292332 | M11: 327878 | N11: 344758 | O11: 362438
A12: Goodwill | B12: 48175 | C12: 48081 | D12: 47647 | E12: 47325 | F12: 47288 | G12: 47507 | H12: 47471 | I12: 47823 | J12: 49248 | K12: 50315 | L12: 51662 | M12: 52634 | N12: 52565 | O12: 52731
A13: Diluted EPS ($) | B13: 5.2 | C13: 4.34 | D13: 5.29 | E13: 6 | F13: 6.19 | G13: 6.31 | H13: 9 | I13: 10.72 | J13: 8.88 | K13: 15.36 | L13: 12.09 | M13: 16.23 | N13: 19.75 | O13: 20.02
A14: Dividends declared per share ($) | B14: 1.2 | C14: 1.44 | D14: 1.58 | E14: 1.72 | F14: 1.88 | G14: 2.12 | H14: 2.72 | I14: 3.4 | J14: 3.6 | K14: 3.8 | L14: 4 | M14: 4.1 | N14: 4.8 | O14: 5.8
A15: Buybacks | E15: 5616 | F15: 9082 | G15: 15410 | H15: 19983 | I15: 24001 | J15: 6517 | K15: 18408 | L15: 3162 | M15: 9824 | N15: 18830 | O15: 31591
A16: Diluted shares (mm) | B16: 3822.2 | C16: 3814.9 | D16: 3797.5 | E16: 3773.6 | F16: 3690 | G16: 3576.8 | H16: 3414 | I16: 3230.4 | J16: 3087.4 | K16: 3026.6 | L16: 2970 | M16: 2943.1 | N16: 2879 | O16: 2781.5
A18: Efficiency ratio (expense / revenue) | B18: =B7/(B5+B6) -> 0.66709608 | C18: =C7/(C5+C6) -> 0.7237257 | D18: =D7/(D5+D6) -> 0.64422996 | E18: =E7/(E5+E6) -> 0.63087564 | F18: =F7/(F5+F6) -> 0.58685499 | G18: =G7/(G5+G6) -> 0.59098357 | H18: =H7/(H5+H6) -> 0.58049511 | I18: =I7/(I5+I6) -> 0.56402523 | ... O18: =O7/(O5+O6) -> 0.52420703
A19: Provision / net interest income | B19: =B8/B5 -> 0.075372968 | C19: =C8/C5 -> 0.0051940257 | D19: =D8/D5 -> 0.071939313 | E19: =E8/E5 -> 0.087956792 | F19: =F8/F5 -> 0.11633357 | G19: =G8/G5 -> 0.10559515 | H19: =H8/H5 -> 0.088468734 | I19: =I8/I5 -> 0.097563106 | ... O19: =O8/O5 -> 0.14890563
A20: Return on total equity (net income / year-end equity) | B20: =B9/B11 -> 0.10429806 | C20: =C9/C11 -> 0.084696323 | D20: =D9/D11 -> 0.093838871 | E20: =E9/E11 -> 0.098726436 | F20: =F9/F11 -> 0.097301231 | G20: =G9/G11 -> 0.095587286 | H20: =H9/H11 -> 0.12659689 | I20: =I9/I11 -> 0.13940611 | ... O20: =O9/O11 -> 0.15740071
A21: Dividend payout (DPS / EPS) | B21: =B14/B13 -> 0.23076923 | C21: =C14/C13 -> 0.33179724 | D21: =D14/D13 -> 0.29867675 | E21: =E14/E13 -> 0.28666667 | F21: =F14/F13 -> 0.30371567 | G21: =G14/G13 -> 0.33597464 | H21: =H14/H13 -> 0.30222222 | I21: =I14/I13 -> 0.31716418 | ... O21: =O14/O13 -> 0.28971029
A23: 2020 shows the credit-cycle pattern: provisions jumped to $17.5bn and net income fell 20%. In 2021 reserve releases (negative provision) lifted earnings to a record.

Sheet RI model
A1: Residual income model by scenario ($mm). Value = TCE today + PV of (net income - r x opening TCE).
A3: Bear case
A4: $mm | C4: Y0 | D4: Y1 | E4: Y2 | F4: Y3 | G4: Y4 | H4: Y5 | I4: Y6 | J4: Y7 | K4: Y8 | L4: Y9 | M4: Y10
A5: ROTE | D5: =Inputs!D31 -> 0.19 | E5: =Inputs!E31 -> 0.12 | F5: =Inputs!F31 -> 0.11 | G5: =Inputs!G31 -> 0.14 | H5: =Inputs!H31 -> 0.15 | I5: =Inputs!I31 -> 0.15 | J5: =Inputs!J31 -> 0.15 | K5: =Inputs!K31 -> 0.15 | ... M5: =Inputs!M31 -> 0.15
A6: Opening TCE | D6: =C9 -> 298670.54 | E6: =D9 -> 329881.61 | F6: =E9 -> 351653.79 | G6: =F9 -> 372928.85 | H6: =G9 -> 401644.37 | I6: =H9 -> 434780.03 | J6: =I9 -> 470649.38 | K6: =J9 -> 509477.96 | ... M6: =L9 -> 597009.45
A7: Net income to common | D7: =D5*D6 -> 56747.402 | E7: =E5*E6 -> 39585.793 | F7: =F5*F6 -> 38681.917 | G7: =G5*G6 -> 52210.039 | H7: =H5*H6 -> 60246.655 | I7: =I5*I6 -> 65217.005 | J7: =J5*J6 -> 70597.407 | K7: =K5*K6 -> 76421.694 | ... M7: =M5*M6 -> 89551.418
A8: Distributions (dividends + buybacks) | D8: =-Inputs!$C$33*D7 -> -25536.331 | E8: =-Inputs!$C$33*E7 -> -17813.607 | F8: =-Inputs!$C$33*F7 -> -17406.863 | G8: =-Inputs!$C$33*G7 -> -23494.517 | H8: =-Inputs!$C$33*H7 -> -27110.995 | I8: =-Inputs!$C$33*I7 -> -29347.652 | J8: =-Inputs!$C$33*J7 -> -31768.833 | K8: =-Inputs!$C$33*K7 -> -34389.762 | ... M8: =-Inputs!$C$33*M7 -> -40298.138
A9: Closing TCE | C9: =Inputs!$B$11 -> 298670.54 | D9: =D6+D7+D8 -> 329881.61 | E9: =E6+E7+E8 -> 351653.79 | F9: =F6+F7+F8 -> 372928.85 | G9: =G6+G7+G8 -> 401644.37 | H9: =H6+H7+H8 -> 434780.03 | I9: =I6+I7+I8 -> 470649.38 | J9: =J6+J7+J8 -> 509477.96 | K9: =K6+K7+K8 -> 551509.89 | ... M9: =M6+M7+M8 -> 646262.73
A10: Equity charge (r x opening TCE) | D10: =-Inputs!$B$21*D6 -> -30315.806 | E10: =-Inputs!$B$21*E6 -> -33483.808 | F10: =-Inputs!$B$21*F6 -> -35693.739 | G10: =-Inputs!$B$21*G6 -> -37853.21 | H10: =-Inputs!$B$21*H6 -> -40767.908 | I10: =-Inputs!$B$21*I6 -> -44131.26 | J10: =-Inputs!$B$21*J6 -> -47772.089 | K10: =-Inputs!$B$21*K6 -> -51713.286 | ... M10: =-Inputs!$B$21*M6 -> -60597.952
A11: Residual income | D11: =D7+D10 -> 26431.596 | E11: =E7+E10 -> 6101.985 | F11: =F7+F10 -> 2988.1781 | G11: =G7+G10 -> 14356.828 | H11: =H7+H10 -> 19478.748 | I11: =I7+I10 -> 21085.745 | J11: =J7+J10 -> 22825.318 | K11: =K7+K10 -> 24708.407 | ... M11: =M7+M10 -> 28953.466
A12: Discount factor | D12: =1/(1+Inputs!$B$21)^1 -> 0.90785087 | E12: =1/(1+Inputs!$B$21)^2 -> 0.8241932 | F12: =1/(1+Inputs!$B$21)^3 -> 0.74824451 | G12: =1/(1+Inputs!$B$21)^4 -> 0.67929443 | H12: =1/(1+Inputs!$B$21)^5 -> 0.61669803 | I12: =1/(1+Inputs!$B$21)^6 -> 0.55986985 | J12: =1/(1+Inputs!$B$21)^7 -> 0.50827832 | K12: =1/(1+Inputs!$B$21)^8 -> 0.46144092 | L12: =1/(1+Inputs!$B$21)^9 -> 0.41891954 | M12: =1/(1+Inputs!$B$21)^10 -> 0.38031647
A13: PV of residual income | D13: =D11*D12 -> 23995.947 | E13: =E11*E12 -> 5029.2146 | F13: =F11*F12 -> 2235.8879 | G13: =G11*G12 -> 9752.5135 | H13: =H11*H12 -> 12012.505 | I13: =I11*I12 -> 11805.273 | J13: =J11*J12 -> 11601.615 | K13: =K11*K12 -> 11401.47 | ... M13: =M11*M12 -> 11011.48
A15: Long-run ROTE | C15: =Inputs!C32 -> 0.15
A16: Terminal residual income (year 11) | C16: =(C15-Inputs!$B$21)*M9 -> 31342.127
A17: Terminal value at Y10 | C17: =C16/(Inputs!$B$21-Inputs!$B$22) -> 509607.36
A18: PV of terminal value | C18: =C17*M12 -> 193812.07
A19: Sum of PV of residual income (Y1-Y10) | C19: =SUM(D13:M13) -> 110050.68
A20: Tangible common equity today | C20: =Inputs!$B$11 -> 298670.54
A21: Equity value | C21: =C20+C19+C18 -> 602533.29
A22: Value per share ($) | C22: =C21/Inputs!$B$6 -> 227.23818
A23: Upside / (downside) vs price | C23: =C22/Inputs!$B$5-1 -> -0.33110155
A24: Implied P/TBV | C24: =C22/Inputs!$B$10 -> 2.0173844
A25: Terminal value as % of equity value | C25: =C18/C21 -> 0.32166201
A28: Base case
A29: $mm | C29: Y0 | D29: Y1 | E29: Y2 | F29: Y3 | G29: Y4 | H29: Y5 | I29: Y6 | J29: Y7 | K29: Y8 | L29: Y9 | M29: Y10
A30: ROTE | D30: =Inputs!D36 -> 0.2 | E30: =Inputs!E36 -> 0.19 | F30: =Inputs!F36 -> 0.18 | G30: =Inputs!G36 -> 0.175 | H30: =Inputs!H36 -> 0.17 | I30: =Inputs!I36 -> 0.17 | J30: =Inputs!J36 -> 0.17 | K30: =Inputs!K36 -> 0.17 | ... M30: =Inputs!M36 -> 0.17
A31: Opening TCE | D31: =C34 -> 298670.54 | E31: =D34 -> 322564.18 | F31: =E34 -> 347079.06 | G31: =F34 -> 372068.75 | H31: =G34 -> 398113.56 | I31: =H34 -> 425185.28 | J31: =I34 -> 454097.88 | K31: =J34 -> 484976.54 | ... M31: =L34 -> 553175.88
A32: Net income to common | D32: =D30*D31 -> 59734.107 | E32: =E30*E31 -> 61287.194 | F32: =F30*F31 -> 62474.23 | G32: =G30*G31 -> 65112.031 | H32: =H30*H31 -> 67679.306 | I32: =I30*I31 -> 72281.498 | J32: =J30*J31 -> 77196.64 | K32: =K30*K31 -> 82446.012 | ... M32: =M30*M31 -> 94039.9
A33: Distributions (dividends + buybacks) | D33: =-Inputs!$C$38*D32 -> -35840.464 | E33: =-Inputs!$C$38*E32 -> -36772.316 | F33: =-Inputs!$C$38*F32 -> -37484.538 | G33: =-Inputs!$C$38*G32 -> -39067.219 | H33: =-Inputs!$C$38*H32 -> -40607.583 | I33: =-Inputs!$C$38*I32 -> -43368.899 | J33: =-Inputs!$C$38*J32 -> -46317.984 | K33: =-Inputs!$C$38*K32 -> -49467.607 | ... M33: =-Inputs!$C$38*M32 -> -56423.94
A34: Closing TCE | C34: =Inputs!$B$11 -> 298670.54 | D34: =D31+D32+D33 -> 322564.18 | E34: =E31+E32+E33 -> 347079.06 | F34: =F31+F32+F33 -> 372068.75 | G34: =G31+G32+G33 -> 398113.56 | H34: =H31+H32+H33 -> 425185.28 | I34: =I31+I32+I33 -> 454097.88 | J34: =J31+J32+J33 -> 484976.54 | K34: =K31+K32+K33 -> 517954.94 | ... M34: =M31+M32+M33 -> 590791.84
A35: Equity charge (r x opening TCE) | D35: =-Inputs!$B$21*D31 -> -30315.806 | E35: =-Inputs!$B$21*E31 -> -32741.071 | F35: =-Inputs!$B$21*F31 -> -35229.392 | G35: =-Inputs!$B$21*G31 -> -37765.908 | H35: =-Inputs!$B$21*H31 -> -40409.522 | I35: =-Inputs!$B$21*I31 -> -43157.369 | J35: =-Inputs!$B$21*J31 -> -46092.07 | K35: =-Inputs!$B$21*K31 -> -49226.331 | ... M35: =-Inputs!$B$21*M31 -> -56148.735
A36: Residual income | D36: =D32+D35 -> 29418.301 | E36: =E32+E35 -> 28546.123 | F36: =F32+F35 -> 27244.838 | G36: =G32+G35 -> 27346.123 | H36: =H32+H35 -> 27269.784 | I36: =I32+I35 -> 29124.129 | J36: =J32+J35 -> 31104.57 | K36: =K32+K35 -> 33219.681 | ... M36: =M32+M35 -> 37891.165
A37: Discount factor | D37: =1/(1+Inputs!$B$21)^1 -> 0.90785087 | E37: =1/(1+Inputs!$B$21)^2 -> 0.8241932 | F37: =1/(1+Inputs!$B$21)^3 -> 0.74824451 | G37: =1/(1+Inputs!$B$21)^4 -> 0.67929443 | H37: =1/(1+Inputs!$B$21)^5 -> 0.61669803 | I37: =1/(1+Inputs!$B$21)^6 -> 0.55986985 | J37: =1/(1+Inputs!$B$21)^7 -> 0.50827832 | K37: =1/(1+Inputs!$B$21)^8 -> 0.46144092 | L37: =1/(1+Inputs!$B$21)^9 -> 0.41891954 | M37: =1/(1+Inputs!$B$21)^10 -> 0.38031647
A38: PV of residual income | D38: =D36*D37 -> 26707.43 | E38: =E36*E37 -> 23527.521 | F38: =F36*F37 -> 20385.801 | G38: =G36*G37 -> 18576.069 | H38: =H36*H37 -> 16817.222 | I38: =I36*I37 -> 16305.722 | J38: =J36*J37 -> 15809.779 | K38: =K36*K37 -> 15328.92 | ... M38: =M36*M37 -> 14410.634
A40: Long-run ROTE | C40: =Inputs!C37 -> 0.17
A41: Terminal residual income (year 11) | C41: =(C40-Inputs!$B$21)*M34 -> 40467.764
A42: Terminal value at Y10 | C42: =C41/(Inputs!$B$21-Inputs!$B$22) -> 657985.68
A43: PV of terminal value | C43: =C42*M37 -> 250242.79
A44: Sum of PV of residual income (Y1-Y10) | C44: =SUM(D38:M38) -> 182731.78
A45: Tangible common equity today | C45: =Inputs!$B$11 -> 298670.54
...

Sheet Reverse
A1: What does the price imply? Steady state: justified P/TBV = (ROTE - g) / (r - g)
A3: Current P/TBV | C3: =Inputs!B12 -> 3.0159801
A4: Cost of equity (r) | C4: =Inputs!B21 -> 0.1015025
A5: Terminal growth (g) | C5: =Inputs!B22 -> 0.04
A6: ROTE the price implies, forever | C6: =C3*(C4-C5)+C5 -> 0.22549032
A7: vs management through-the-cycle target | C7: 0.17
A8: vs Q3 2026 core ROTCE | C8: 0.21
A11: Value per share ($), steady-state formula: cost of equity (rows) x sustained ROTE (columns)
A12: r \ ROTE | C12: 0.13 | D12: 0.15 | E12: 0.17 | F12: 0.19 | G12: 0.21 | H12: 0.23 | I12: 0.25
A13: 0.08 | C13: =Inputs!$B$10*(C$12-$C$5)/($A13-$C$5) -> 253.44 | D13: =Inputs!$B$10*(D$12-$C$5)/($A13-$C$5) -> 309.76 | E13: =Inputs!$B$10*(E$12-$C$5)/($A13-$C$5) -> 366.08 | F13: =Inputs!$B$10*(F$12-$C$5)/($A13-$C$5) -> 422.4 | G13: =Inputs!$B$10*(G$12-$C$5)/($A13-$C$5) -> 478.72 | H13: =Inputs!$B$10*(H$12-$C$5)/($A13-$C$5) -> 535.04 | I13: =Inputs!$B$10*(I$12-$C$5)/($A13-$C$5) -> 591.36
A14: 0.085 | C14: =Inputs!$B$10*(C$12-$C$5)/($A14-$C$5) -> 225.28 | D14: =Inputs!$B$10*(D$12-$C$5)/($A14-$C$5) -> 275.34222 | E14: =Inputs!$B$10*(E$12-$C$5)/($A14-$C$5) -> 325.40444 | F14: =Inputs!$B$10*(F$12-$C$5)/($A14-$C$5) -> 375.46667 | G14: =Inputs!$B$10*(G$12-$C$5)/($A14-$C$5) -> 425.52889 | H14: =Inputs!$B$10*(H$12-$C$5)/($A14-$C$5) -> 475.59111 | I14: =Inputs!$B$10*(I$12-$C$5)/($A14-$C$5) -> 525.65333
A15: 0.09 | C15: =Inputs!$B$10*(C$12-$C$5)/($A15-$C$5) -> 202.752 | D15: =Inputs!$B$10*(D$12-$C$5)/($A15-$C$5) -> 247.808 | E15: =Inputs!$B$10*(E$12-$C$5)/($A15-$C$5) -> 292.864 | F15: =Inputs!$B$10*(F$12-$C$5)/($A15-$C$5) -> 337.92 | G15: =Inputs!$B$10*(G$12-$C$5)/($A15-$C$5) -> 382.976 | H15: =Inputs!$B$10*(H$12-$C$5)/($A15-$C$5) -> 428.032 | I15: =Inputs!$B$10*(I$12-$C$5)/($A15-$C$5) -> 473.088
A16: 0.095 | C16: =Inputs!$B$10*(C$12-$C$5)/($A16-$C$5) -> 184.32 | D16: =Inputs!$B$10*(D$12-$C$5)/($A16-$C$5) -> 225.28 | E16: =Inputs!$B$10*(E$12-$C$5)/($A16-$C$5) -> 266.24 | F16: =Inputs!$B$10*(F$12-$C$5)/($A16-$C$5) -> 307.2 | G16: =Inputs!$B$10*(G$12-$C$5)/($A16-$C$5) -> 348.16 | H16: =Inputs!$B$10*(H$12-$C$5)/($A16-$C$5) -> 389.12 | I16: =Inputs!$B$10*(I$12-$C$5)/($A16-$C$5) -> 430.08
A17: 0.1 | C17: =Inputs!$B$10*(C$12-$C$5)/($A17-$C$5) -> 168.96 | D17: =Inputs!$B$10*(D$12-$C$5)/($A17-$C$5) -> 206.50667 | E17: =Inputs!$B$10*(E$12-$C$5)/($A17-$C$5) -> 244.05333 | F17: =Inputs!$B$10*(F$12-$C$5)/($A17-$C$5) -> 281.6 | G17: =Inputs!$B$10*(G$12-$C$5)/($A17-$C$5) -> 319.14667 | H17: =Inputs!$B$10*(H$12-$C$5)/($A17-$C$5) -> 356.69333 | I17: =Inputs!$B$10*(I$12-$C$5)/($A17-$C$5) -> 394.24
A18: 0.105 | C18: =Inputs!$B$10*(C$12-$C$5)/($A18-$C$5) -> 155.96308 | D18: =Inputs!$B$10*(D$12-$C$5)/($A18-$C$5) -> 190.62154 | E18: =Inputs!$B$10*(E$12-$C$5)/($A18-$C$5) -> 225.28 | F18: =Inputs!$B$10*(F$12-$C$5)/($A18-$C$5) -> 259.93846 | G18: =Inputs!$B$10*(G$12-$C$5)/($A18-$C$5) -> 294.59692 | H18: =Inputs!$B$10*(H$12-$C$5)/($A18-$C$5) -> 329.25538 | I18: =Inputs!$B$10*(I$12-$C$5)/($A18-$C$5) -> 363.91385
A19: 0.11 | C19: =Inputs!$B$10*(C$12-$C$5)/($A19-$C$5) -> 144.82286 | D19: =Inputs!$B$10*(D$12-$C$5)/($A19-$C$5) -> 177.00571 | E19: =Inputs!$B$10*(E$12-$C$5)/($A19-$C$5) -> 209.18857 | F19: =Inputs!$B$10*(F$12-$C$5)/($A19-$C$5) -> 241.37143 | G19: =Inputs!$B$10*(G$12-$C$5)/($A19-$C$5) -> 273.55429 | H19: =Inputs!$B$10*(H$12-$C$5)/($A19-$C$5) -> 305.73714 | I19: =Inputs!$B$10*(I$12-$C$5)/($A19-$C$5) -> 337.92
A20: 0.12 | C20: =Inputs!$B$10*(C$12-$C$5)/($A20-$C$5) -> 126.72 | D20: =Inputs!$B$10*(D$12-$C$5)/($A20-$C$5) -> 154.88 | E20: =Inputs!$B$10*(E$12-$C$5)/($A20-$C$5) -> 183.04 | F20: =Inputs!$B$10*(F$12-$C$5)/($A20-$C$5) -> 211.2 | G20: =Inputs!$B$10*(G$12-$C$5)/($A20-$C$5) -> 239.36 | H20: =Inputs!$B$10*(H$12-$C$5)/($A20-$C$5) -> 267.52 | I20: =Inputs!$B$10*(I$12-$C$5)/($A20-$C$5) -> 295.68
A22: Current price ($) | C22: =Inputs!B5 -> 339.72

Sheet Peers
A1: US large banks, same method for all: TBVPS = book value per share (Yahoo) - (goodwill + intangibles) / shares (SEC XBRL); ROTE = TTM net income to common / TCE.
A2: Prices 2026-10-16. JPM's computed TBVPS ($111.96) differs from the reported $112.64 by deferred-tax netting.
A4: Bank | B4: Price | C4: TBVPS | D4: ROTE (TTM) | E4: P/TBV | F4: P/E (TTM) | G4: Justified P/TBV* | H4: Gap
A5: JPM | B5: 339.72 | C5: 111.96 | D5: 0.217 | E5: =B5/C5 -> 3.034298 | F5: 13.98 | G5: =(D5-Inputs!$B$22)/(Inputs!$B$21-Inputs!$B$22) -> 2.8779318 | H5: =E5/G5-1 -> 0.054332828
A6: BAC | B6: 51.23 | C6: 29.13 | D6: 0.151 | E6: =B6/C6 -> 1.758668 | F6: 11.65 | G6: =(D6-Inputs!$B$22)/(Inputs!$B$21-Inputs!$B$22) -> 1.8048047 | H6: =E6/G6-1 -> -0.025563233
A7: WFC | B7: 83.87 | C7: 46.11 | D7: 0.1588 | E7: =B7/C7 -> 1.8189113 | F7: 11.46 | G7: =(D7-Inputs!$B$22)/(Inputs!$B$21-Inputs!$B$22) -> 1.9316288 | H7: =E7/G7-1 -> -0.058353601
A8: C | B8: 124.26 | C8: 101.67 | D8: 0.1047 | E8: =B8/C8 -> 1.2221894 | F8: 11.67 | G8: =(D8-Inputs!$B$22)/(Inputs!$B$21-Inputs!$B$22) -> 1.0519898 | H8: =E8/G8-1 -> 0.16178834
A9: GS | B9: 881.26 | C9: 340.41 | D9: 0.2144 | E9: =B9/C9 -> 2.5888194 | F9: 12.07 | G9: =(D9-Inputs!$B$22)/(Inputs!$B$21-Inputs!$B$22) -> 2.8356571 | H9: =E9/G9-1 -> -0.087047804
A10: MS | B10: 180.57 | C10: 53.17 | D10: 0.2377 | E10: =B10/C10 -> 3.396088 | F10: 14.29 | G10: =(D10-Inputs!$B$22)/(Inputs!$B$21-Inputs!$B$22) -> 3.2145035 | H10: =E10/G10-1 -> 0.056489142
A12: * If today's TTM ROTE lasted forever, at JPM's cost of equity and growth. Gap > 0 means the price asks for more than today's returns.
