Workbook

Sheet Summary
A1: Micron Technology (MU): three-scenario DCF
A2: Valuation date 2026-10-16. $mm unless stated. Change blue/yellow cells in 'Inputs'; everything else recalculates.
B4: Bear | C4: Base | D4: Bull | E4: Prob.-weighted
A5: FY2027 revenue | B5: =DCF!D5 -> 213100.8 | C5: =DCF!D39 -> 275699.16 | D5: =DCF!D73 -> 286354.2
A6: FY2031 revenue | B6: =DCF!H5 -> 86392.13 | C6: =DCF!H39 -> 151110.71 | D6: =DCF!H73 -> 367759.33
A7: Normalised operating margin | B7: =DCF!C19 -> 0.2 | C7: =DCF!C53 -> 0.35 | D7: =DCF!C87 -> 0.5
A8: Enterprise value | B8: =DCF!C26 -> 183050.93 | C8: =DCF!C60 -> 530279.34 | D8: =DCF!C94 -> 1148091.2
A9: Equity value | B9: =DCF!C30 -> 238604.93 | C9: =DCF!C64 -> 585833.34 | D9: =DCF!C98 -> 1203645.2
A10: Value per share ($) | B10: =DCF!C31 -> 208.02522 | C10: =DCF!C65 -> 510.75269 | D10: =DCF!C99 -> 1049.3855 | E10: =SUMPRODUCT(B10:D10,B13:D13) -> 527.66102
A11: Upside / (downside) | B11: =DCF!C32 -> -0.76329568 | C11: =DCF!C66 -> -0.41883313 | D11: =DCF!C100 -> 0.19405753 | E11: =E10/Inputs!B5-1 -> -0.39959376
A12: Terminal value as % of EV | B12: =DCF!C33 -> 0.30504667 | C12: =DCF!C67 -> 0.322324 | D12: =DCF!C101 -> 0.51759655
A13: Probability | B13: =Inputs!B56 -> 0.3 | C13: =Inputs!B57 -> 0.5 | D13: =Inputs!B58 -> 0.2
A15: Current share price ($) | B15: =Inputs!B5 -> 878.84
A16: WACC | B16: =Inputs!B23 -> 0.14171708
A17: Margin from FY29 needed to justify the price | B17: ='Reverse DCF'!C14 -> 0.93513151
A18: Through-cycle operating margin FY15-25 | B18: =Historical!B27 -> 0.17471715
A19: Forward P/E: Micron / peer median | B19: =Comps!D5 -> 4.2 | C19: =Comps!D12 -> 4.9
A21: Legend: blue = input, black = formula, green = link to another sheet, yellow = key assumption.
A22: Sources: SEC EDGAR (10-K FY26 filed 2026-10-09; 8-K earnings release 2026-09-30); Yahoo Finance 2026-10-16.
A23: Personal research, not investment advice.

Sheet Inputs
A1: Micron Technology (MU): inputs and scenario levers ($mm unless stated)
A2: Blue = hardcoded input. Yellow = key assumption. Black = formula. Sources in column I.
A4: Market data and capital structure
A5: Share price ($) | B5: 878.84 | I5: Yahoo Finance, close 2026-10-16
A6: Diluted shares (mm) | B6: 1147 | I6: FQ4-26 GAAP net income $37,701mm / diluted EPS $32.87 (8-K exhibit 99.1, 2026-09-30)
A7: Cash, marketable investments and restricted cash | B7: 73480 | I7: FY26 earnings release (8-K exhibit 99.1, 2026-09-30)
A8: Debt (notes) | B8: 2792 | I8: 10-K FY26, XBRL LongTermDebt at 2026-09-03
A9: Finance lease liabilities | B9: 2387 | I9: 10-K FY26, XBRL FinanceLeaseLiability at 2026-09-03
A10: Customer contract liability deposits | B10: 12747 | I10: FY26 cash flow: proceeds from customer contract liability deposits (Strategic Customer Agreements)
A11: Treat customer deposits as debt? (1 = yes, 0 = no) | B11: 1 | I11: Prepayments settled in future product; debt-like by default (conservative)
A13: Discount rate
A14: Risk-free rate (US 10-year) | B14: 0.051 | I14: ^TNX close 2026-10-16: 5.10%
A15: Raw beta (5y monthly) | B15: 2.23 | I15: Yahoo Finance
A16: Adjusted beta (Blume: 0.67 x raw + 0.33) | B16: =0.67*B15+0.33 -> 1.8241 | I16: Formula
A17: Equity risk premium | B17: 0.05 | I17: Assumption (author)
A18: Cost of equity | B18: =B14+B16*B17 -> 0.142205 | I18: CAPM
A19: Pre-tax cost of debt | B19: 0.055 | I19: Assumption: 10-year yield + ~40bp (investment grade)
A20: Tax rate | B20: 0.15 | I20: FY26 effective rate 14.8% (tax $14,761mm / pretax $99,671mm, 10-K)
A21: Market capitalisation | B21: =B5*B6 -> 1008029.5 | I21: Formula
A22: Debt incl. finance leases | B22: =B8+B9 -> 5179 | I22: Formula
A23: WACC | B23: =(B21*B18+B22*B19*(1-B20))/(B21+B22) -> 0.14171708 | I23: Formula, market-value weights
A25: Operating and terminal assumptions
A26: Terminal growth | B26: 0.03 | I26: Assumption: roughly nominal GDP
A27: Return on new invested capital (terminal) | B27: 0.15 | I27: Assumption: terminal reinvestment rate = g / RONIC
A28: Change in NWC as % of change in revenue | B28: 0.1 | I28: Assumption (inventory + receivables, net of payables)
A29: D&A catch-up to prior-year capex (per year) | B29: 0.2 | I29: Assumption: D&A(t) = D&A(t-1) + 20% x (Capex(t-1) - D&A(t-1))
A30: FY26 revenue | B30: 133188 | I30: 10-K FY26
A31: FY26 D&A | B31: 9503 | I31: 10-K FY26 cash flow statement
A32: FY26 capex, net | B32: 27370 | I32: FY26 earnings release: investments in capital expenditures, net $27.37bn
A34: Scenarios (fiscal years end in early September)
C35: FY2027 | D35: FY2028 | E35: FY2029 | F35: FY2030 | G35: FY2031
A37: Bear case | I37: FY27 at the lowest analyst estimate, then a 2023-style bust. Normalised margin ~ FY15-25 through-cycle average.
A38: Revenue growth | C38: 0.6 | D38: -0.45 | E38: -0.35 | F38: 0.05 | G38: 0.08 | I38: Consensus (Yahoo Finance, 2026-10-16): FY27 revenue $275.5bn (+107%, low $212.4bn), FY28 $318.9bn (+16%, low $224.2bn).
A39: Operating margin | C39: 0.72 | D39: 0.35 | E39: 0.1 | F39: 0.15 | G39: 0.2
A40: Capex, net ($mm) | C40: 45000 | D40: 30000 | E40: 20000 | F40: 20000 | G40: 21000
A41: Normalised (terminal) operating margin | C41: 0.2
A43: Base case | I43: Consensus for FY27-28, then the cycle turns; margins normalise above history (35%) thanks to HBM mix.
A44: Revenue growth | C44: 1.07 | D44: 0.16 | E44: -0.25 | F44: -0.3 | G44: -0.1 | I44: FY27 Q1 guidance: revenue $61.5bn +/- 1.5bn, gross margin ~86% (8-K 2026-09-30).
A45: Operating margin | C45: 0.8 | D45: 0.75 | E45: 0.55 | F45: 0.4 | G45: 0.35
A46: Capex, net ($mm) | C46: 50000 | D46: 60000 | E46: 50000 | F46: 45000 | G46: 42000
...

Sheet Historical
A1: Micron: historical financials ($mm). Fiscal years end late August / early September.
A2: Source: SEC EDGAR XBRL company facts (10-K filings), CIK 0000723125.
A4: $mm | B4: 2014 | C4: 2015 | D4: 2016 | E4: 2017 | F4: 2018 | G4: 2019 | H4: 2020 | I4: 2021 | J4: 2022 | K4: 2023 | L4: 2024 | M4: 2025 | N4: 2026
A5: Revenue | B5: 16358 | C5: 16192 | D5: 12399 | E5: 20322 | F5: 30391 | G5: 23406 | H5: 21435 | I5: 27705 | J5: 30758 | K5: 15540 | L5: 25111 | M5: 37378 | N5: 133188
A6: Cost of goods sold | B6: 10921 | C6: 10977 | D6: 9894 | E6: 11886 | F6: 12500 | G6: 12704 | H6: 14883 | I6: 17282 | J6: 16860 | K6: 16956 | L6: 19498 | M6: 22505 | N6: 25684
A7: Gross profit | B7: =B5-B6 -> 5437 | C7: =C5-C6 -> 5215 | D7: =D5-D6 -> 2505 | E7: =E5-E6 -> 8436 | F7: =F5-F6 -> 17891 | G7: =G5-G6 -> 10702 | H7: =H5-H6 -> 6552 | I7: =I5-I6 -> 10423 | ... N7: =N5-N6 -> 107504
A8: R&D | B8: 1371 | C8: 1540 | D8: 1617 | E8: 1824 | F8: 2141 | G8: 2441 | H8: 2600 | I8: 2663 | J8: 3116 | K8: 3114 | L8: 3430 | M8: 3798 | N8: 5650
A9: SG&A | B9: 707 | C9: 719 | D9: 659 | E9: 743 | F9: 813 | G9: 836 | H9: 881 | I9: 894 | J9: 1066 | K9: 920 | L9: 1129 | M9: 1205 | N9: 1947
A10: Operating income | B10: 3087 | C10: 2998 | D10: 168 | E10: 5868 | F10: 14994 | G10: 7376 | H10: 3003 | I10: 6283 | J10: 9702 | K10: -5745 | L10: 1304 | M10: 9770 | N10: 99340
A11: Net income | B11: 3045 | C11: 2899 | D11: -276 | E11: 5089 | F11: 14135 | G11: 6313 | H11: 2687 | I11: 5861 | J11: 8687 | K11: -5833 | L11: 778 | M11: 8539 | N11: 84969
A12: D&A | B12: 2270 | C12: 2805 | D12: 2980 | E12: 3861 | F12: 4759 | G12: 5424 | H12: 5650 | I12: 6214 | J12: 7116 | K12: 7756 | L12: 7780 | M12: 8352 | N12: 9503
A13: Stock-based compensation | B13: 115 | C13: 168 | D13: 191 | E13: 215 | F13: 198 | G13: 243 | H13: 328 | I13: 378 | J13: 514 | K13: 596 | L13: 833 | M13: 972 | N13: 1333
A14: Cash from operations | C14: 5208 | D14: 3168 | E14: 8153 | F14: 17400 | G14: 13189 | H14: 8306 | I14: 12468 | J14: 15181 | K14: 1559 | L14: 8507 | M14: 17525 | N14: 89675
A15: Capex (PP&E purchases) | B15: 3107 | C15: 4021 | D15: 5817 | E15: 4734 | F15: 8879 | G15: 9780 | H15: 8223 | I15: 10030 | J15: 12067 | K15: 7676 | L15: 8386 | M15: 15857 | N15: 30712
A16: Free cash flow (CFO - capex) | B16: =IF(B14="","",B14-B15) | C16: =IF(C14="","",C14-C15) -> 1187 | D16: =IF(D14="","",D14-D15) -> -2649 | E16: =IF(E14="","",E14-E15) -> 3419 | F16: =IF(F14="","",F14-F15) -> 8521 | G16: =IF(G14="","",G14-G15) -> 3409 | H16: =IF(H14="","",H14-H15) -> 83 | I16: =IF(I14="","",I14-I15) -> 2438 | ... N16: =IF(N14="","",N14-N15) -> 58963
A17: Diluted shares (mm) | B17: 1198 | C17: 1170 | D17: 1036 | E17: 1154 | F17: 1229 | G17: 1143 | H17: 1131 | I17: 1141 | J17: 1122 | K17: 1093 | L17: 1118 | M17: 1125 | N17: 1143
A18: Diluted EPS ($) | B18: =B11/B17 -> 2.5417362 | C18: =C11/C17 -> 2.4777778 | D18: =D11/D17 -> -0.26640927 | E18: =E11/E17 -> 4.4098787 | F18: =F11/F17 -> 11.501221 | G18: =G11/G17 -> 5.5231846 | H18: =H11/H17 -> 2.3757737 | I18: =I11/I17 -> 5.1367222 | ... N18: =N11/N17 -> 74.338583
A20: Gross margin | B20: =B7/B5 -> 0.3323756 | C20: =C7/C5 -> 0.32207263 | D20: =D7/D5 -> 0.20203242 | E20: =E7/E5 -> 0.41511662 | F20: =F7/F5 -> 0.58869402 | G20: =G7/G5 -> 0.45723319 | H20: =H7/H5 -> 0.3056683 | I20: =I7/I5 -> 0.37621368 | ... N20: =N7/N5 -> 0.8071598
A21: Operating margin | B21: =B10/B5 -> 0.188715 | C21: =C10/C5 -> 0.18515316 | D21: =D10/D5 -> 0.01354948 | E21: =E10/E5 -> 0.28875111 | F21: =F10/F5 -> 0.49336975 | G21: =G10/G5 -> 0.31513287 | H21: =H10/H5 -> 0.14009797 | I21: =I10/I5 -> 0.22678217 | ... N21: =N10/N5 -> 0.74586299
A22: FCF margin | B22: =IF(B16="","",B16/B5) | C22: =IF(C16="","",C16/C5) -> 0.073307806 | D22: =IF(D16="","",D16/D5) -> -0.21364626 | E22: =IF(E16="","",E16/E5) -> 0.16824131 | F22: =IF(F16="","",F16/F5) -> 0.28037906 | G22: =IF(G16="","",G16/G5) -> 0.14564642 | H22: =IF(H16="","",H16/H5) -> 0.0038721717 | I22: =IF(I16="","",I16/I5) -> 0.087998556 | ... N22: =IF(N16="","",N16/N5) -> 0.44270505
A23: Capex / revenue | B23: =B15/B5 -> 0.18993765 | C23: =C15/C5 -> 0.24833251 | D23: =D15/D5 -> 0.46915074 | E23: =E15/E5 -> 0.23294951 | F23: =F15/F5 -> 0.29215886 | G23: =G15/G5 -> 0.41784158 | H23: =H15/H5 -> 0.38362491 | I23: =I15/I5 -> 0.36202851 | ... N23: =N15/N5 -> 0.23059134
A26: Operating margin through the cycle, FY15-FY25
A27: Average | B27: =AVERAGE(C21:M21) -> 0.17471715
A28: Minimum | B28: =MIN(C21:M21) -> -0.36969112
A29: Maximum | B29: =MAX(C21:M21) -> 0.49336975
A30: FY26 (this cycle) | B30: =N21 -> 0.74586299

Sheet DCF
A1: DCF by scenario ($mm). End-of-year discounting from the start of FY27 (September 2026).
A3: Bear case
A4: $mm | C4: FY2026A | D4: FY2027 | E4: FY2028 | F4: FY2029 | G4: FY2030 | H4: FY2031
A5: Revenue | C5: =Inputs!$B$30 -> 133188 | D5: =C5*(1+D6) -> 213100.8 | E5: =D5*(1+E6) -> 117205.44 | F5: =E5*(1+F6) -> 76183.536 | G5: =F5*(1+G6) -> 79992.713 | H5: =G5*(1+H6) -> 86392.13
A6: growth | D6: =Inputs!C38 -> 0.6 | E6: =Inputs!D38 -> -0.45 | F6: =Inputs!E38 -> -0.35 | G6: =Inputs!F38 -> 0.05 | H6: =Inputs!G38 -> 0.08
A7: Operating margin | C7: =C8/C5 -> 0.74586299 | D7: =Inputs!C39 -> 0.72 | E7: =Inputs!D39 -> 0.35 | F7: =Inputs!E39 -> 0.1 | G7: =Inputs!F39 -> 0.15 | H7: =Inputs!G39 -> 0.2
A8: EBIT | C8: =Historical!N10 -> 99340 | D8: =D5*D7 -> 153432.58 | E8: =E5*E7 -> 41021.904 | F8: =F5*F7 -> 7618.3536 | G8: =G5*G7 -> 11998.907 | H8: =H5*H7 -> 17278.426
A9: Taxes | D9: =-D8*Inputs!$B$20 -> -23014.886 | E9: =-E8*Inputs!$B$20 -> -6153.2856 | F9: =-F8*Inputs!$B$20 -> -1142.753 | G9: =-G8*Inputs!$B$20 -> -1799.836 | H9: =-H8*Inputs!$B$20 -> -2591.7639
A10: NOPAT | D10: =D8+D9 -> 130417.69 | E10: =E8+E9 -> 34868.618 | F10: =F8+F9 -> 6475.6006 | G10: =G8+G9 -> 10199.071 | H10: =H8+H9 -> 14686.662
A11: D&A | C11: =Inputs!$B$31 -> 9503 | D11: =C11+Inputs!$B$29*(C12-C11) -> 13076.4 | E11: =D11+Inputs!$B$29*(D12-D11) -> 19461.12 | F11: =E11+Inputs!$B$29*(E12-E11) -> 21568.896 | G11: =F11+Inputs!$B$29*(F12-F11) -> 21255.117 | H11: =G11+Inputs!$B$29*(G12-G11) -> 21004.093
A12: Capex, net | C12: =Inputs!$B$32 -> 27370 | D12: =Inputs!C40 -> 45000 | E12: =Inputs!D40 -> 30000 | F12: =Inputs!E40 -> 20000 | G12: =Inputs!F40 -> 20000 | H12: =Inputs!G40 -> 21000
A13: Change in NWC | D13: =Inputs!$B$28*(D5-C5) -> 7991.28 | E13: =Inputs!$B$28*(E5-D5) -> -9589.536 | F13: =Inputs!$B$28*(F5-E5) -> -4102.1904 | G13: =Inputs!$B$28*(G5-F5) -> 380.91768 | H13: =Inputs!$B$28*(H5-G5) -> 639.9417
A14: Free cash flow | D14: =D10+D11-D12-D13 -> 90502.81 | E14: =E10+E11-E12-E13 -> 33919.274 | F14: =F10+F11-F12-F13 -> 12146.687 | G14: =G10+G11-G12-G13 -> 11073.27 | H14: =H10+H11-H12-H13 -> 14050.814
A15: Discount period (years) | D15: 1 | E15: 2 | F15: 3 | G15: 4 | H15: 5
A16: Discount factor | D16: =1/(1+Inputs!$B$23)^D15 -> 0.87587373 | E16: =1/(1+Inputs!$B$23)^E15 -> 0.76715479 | F16: =1/(1+Inputs!$B$23)^F15 -> 0.67193073 | G16: =1/(1+Inputs!$B$23)^G15 -> 0.58852647 | H16: =1/(1+Inputs!$B$23)^H15 -> 0.51547488
A17: PV of FCF | D17: =D14*D16 -> 79269.033 | E17: =E14*E16 -> 26021.334 | F17: =F14*F16 -> 8161.7322 | G17: =G14*G16 -> 6516.9125 | H17: =H14*H16 -> 7242.8415
A19: Normalised operating margin | C19: =Inputs!C41 -> 0.2
A20: Terminal NOPAT (FY2032) | C20: =H5*(1+Inputs!$B$26)*C19*(1-Inputs!$B$20) -> 15127.262
A21: Terminal reinvestment rate (g / RONIC) | C21: =Inputs!$B$26/Inputs!$B$27 -> 0.2
A22: Terminal FCF (FY2032) | C22: =C20*(1-C21) -> 12101.81
A23: Terminal value at FY2031 | C23: =C22/(Inputs!$B$23-Inputs!$B$26) -> 108325.51
A24: PV of terminal value | C24: =C23*H16 -> 55839.077
A25: Sum of PV of FCF (FY27-31) | C25: =SUM(D17:H17) -> 127211.85
A26: Enterprise value | C26: =C24+C25 -> 183050.93
A27: + Cash and investments | C27: =Inputs!$B$7 -> 73480
A28: - Debt and finance leases | C28: =-Inputs!$B$22 -> -5179
A29: - Customer deposits (if treated as debt) | C29: =-Inputs!$B$10*Inputs!$B$11 -> -12747
A30: Equity value | C30: =SUM(C26:C29) -> 238604.93
A31: Value per share ($) | C31: =C30/Inputs!$B$6 -> 208.02522
A32: Upside / (downside) vs price | C32: =C31/Inputs!$B$5-1 -> -0.76329568
A33: Terminal value as % of EV | C33: =C24/C26 -> 0.30504667
A34: Implied EV / FY2027 EBIT | C34: =C26/D8 -> 1.1930382
A37: Base case
A38: $mm | C38: FY2026A | D38: FY2027 | E38: FY2028 | F38: FY2029 | G38: FY2030 | H38: FY2031
A39: Revenue | C39: =Inputs!$B$30 -> 133188 | D39: =C39*(1+D40) -> 275699.16 | E39: =D39*(1+E40) -> 319811.03 | F39: =E39*(1+F40) -> 239858.27 | G39: =F39*(1+G40) -> 167900.79 | H39: =G39*(1+H40) -> 151110.71
A40: growth | D40: =Inputs!C44 -> 1.07 | E40: =Inputs!D44 -> 0.16 | F40: =Inputs!E44 -> -0.25 | G40: =Inputs!F44 -> -0.3 | H40: =Inputs!G44 -> -0.1
A41: Operating margin | C41: =C42/C39 -> 0.74586299 | D41: =Inputs!C45 -> 0.8 | E41: =Inputs!D45 -> 0.75 | F41: =Inputs!E45 -> 0.55 | G41: =Inputs!F45 -> 0.4 | H41: =Inputs!G45 -> 0.35
A42: EBIT | C42: =Historical!N10 -> 99340 | D42: =D39*D41 -> 220559.33 | E42: =E39*E41 -> 239858.27 | F42: =F39*F41 -> 131922.05 | G42: =G39*G41 -> 67160.315 | H42: =H39*H41 -> 52888.748
A43: Taxes | D43: =-D42*Inputs!$B$20 -> -33083.899 | E43: =-E42*Inputs!$B$20 -> -35978.74 | F43: =-F42*Inputs!$B$20 -> -19788.307 | G43: =-G42*Inputs!$B$20 -> -10074.047 | H43: =-H42*Inputs!$B$20 -> -7933.3123
A44: NOPAT | D44: =D42+D43 -> 187475.43 | E44: =E42+E43 -> 203879.53 | F44: =F42+F43 -> 112133.74 | G44: =G42+G43 -> 57086.268 | H44: =H42+H43 -> 44955.436
...

Sheet Reverse DCF
A1: What do you have to believe? Base-case revenue and capex; FY27-28 margins as in the base case; operating margin from FY29 onwards = m.
A2: Value is linear in m, so FCF splits into a part that does not depend on m (F0) and the part per unit of margin (dF).
A4: $mm | D4: FY2027 | E4: FY2028 | F4: FY2029 | G4: FY2030 | H4: FY2031
A5: Revenue (base case) | D5: =DCF!D39 -> 275699.16 | E5: =DCF!E39 -> 319811.03 | F5: =DCF!F39 -> 239858.27 | G5: =DCF!G39 -> 167900.79 | H5: =DCF!H39 -> 151110.71
A6: Margin fixed at base case (1 = yes) | D6: 1 | E6: 1 | F6: 0 | G6: 0 | H6: 0
A7: F0: FCF with margin = 0 where not fixed | D7: =IF(D6=1,DCF!D48,DCF!D45-DCF!D46-DCF!D47) -> 136300.71 | E7: =IF(E6=1,DCF!E48,DCF!E45-DCF!E46-DCF!E47) -> 159929.46 | F7: =IF(F6=1,DCF!F48,DCF!F45-DCF!F46-DCF!F47) -> -13635.828 | G7: =IF(G6=1,DCF!G48,DCF!G45-DCF!G46-DCF!G47) -> -5109.1351 | H7: =IF(H6=1,DCF!H48,DCF!H45-DCF!H46-DCF!H47) -> -5164.8987
A8: dF: FCF per unit of margin | D8: =IF(D6=1,0,D5*(1-Inputs!$B$20)) -> 0 | E8: =IF(E6=1,0,E5*(1-Inputs!$B$20)) -> 0 | F8: =IF(F6=1,0,F5*(1-Inputs!$B$20)) -> 203879.53 | G8: =IF(G6=1,0,G5*(1-Inputs!$B$20)) -> 142715.67 | H8: =IF(H6=1,0,H5*(1-Inputs!$B$20)) -> 128444.1
A9: Discount period | D9: 1 | E9: 2 | F9: 3 | G9: 4 | H9: 5
A11: Target equity value (price x diluted shares) | C11: =Inputs!B21 -> 1008029.5
A12: PV of F0 + net cash | C12: =SUMPRODUCT(D7:H7/(1+Inputs!$B$23)^D9:H9)+(Inputs!$B$7-Inputs!$B$22-Inputs!$B$10*Inputs!$B$11) -> 282795.3
A13: PV per unit of margin (explicit + terminal) | C13: =SUMPRODUCT(D8:H8/(1+Inputs!$B$23)^D9:H9)+$H$5*(1+Inputs!$B$26)*(1-Inputs!$B$20)*(1-Inputs!$B$26/Inputs!$B$27)/(Inputs!$B$23-Inputs!$B$26)/(1+Inputs!$B$23)^H9 -> 775542.45
A14: Implied operating margin from FY29 onwards | C14: =(C11-C12)/C13 -> 0.93513151
A15: FY15-25 through-cycle average | C15: =Historical!B27 -> 0.17471715
A16: Previous-cycle peak (FY18) | C16: =Historical!F21 -> 0.49336975
A19: Value per share ($): WACC (rows) x operating margin from FY29 onwards (columns)
A20: WACC \ margin | C20: 0.15 | D20: 0.2 | E20: 0.25 | F20: 0.3 | G20: 0.35 | H20: 0.4 | I20: 0.5
A21: 0.1 | C21: =(SUMPRODUCT(($D$7:$H$7+C$20*$D$8:$H$8)/(1+$A21)^$D$9:$H$9)+C$20*$H$5*(1+Inputs!$B$26)*(1-Inputs!$B$20)*(1-Inputs!$B$26/Inputs!$B$27)/($A21-Inputs!$B$26)/(1+$A21)^$H$9+(Inputs!$B$7-Inputs!$B$22-Inputs!$B$10*Inputs!$B$11))/Inputs!$B$6 -> 422.91097 | D21: =(SUMPRODUCT(($D$7:$H$7+D$20*$D$8:$H$8)/(1+$A21)^$D$9:$H$9)+D$20*$H$5*(1+Inputs!$B$26)*(1-Inputs!$B$20)*(1-Inputs!$B$26/Inputs!$B$27)/($A21-Inputs!$B$26)/(1+$A21)^$H$9+(Inputs!$B$7-Inputs!$B$22-Inputs!$B$10*Inputs!$B$11))/Inputs!$B$6 -> 478.2389 | E21: =(SUMPRODUCT(($D$7:$H$7+E$20*$D$8:$H$8)/(1+$A21)^$D$9:$H$9)+E$20*$H$5*(1+Inputs!$B$26)*(1-Inputs!$B$20)*(1-Inputs!$B$26/Inputs!$B$27)/($A21-Inputs!$B$26)/(1+$A21)^$H$9+(Inputs!$B$7-Inputs!$B$22-Inputs!$B$10*Inputs!$B$11))/Inputs!$B$6 -> 533.56684 | F21: =(SUMPRODUCT(($D$7:$H$7+F$20*$D$8:$H$8)/(1+$A21)^$D$9:$H$9)+F$20*$H$5*(1+Inputs!$B$26)*(1-Inputs!$B$20)*(1-Inputs!$B$26/Inputs!$B$27)/($A21-Inputs!$B$26)/(1+$A21)^$H$9+(Inputs!$B$7-Inputs!$B$22-Inputs!$B$10*Inputs!$B$11))/Inputs!$B$6 -> 588.89478 | G21: =(SUMPRODUCT(($D$7:$H$7+G$20*$D$8:$H$8)/(1+$A21)^$D$9:$H$9)+G$20*$H$5*(1+Inputs!$B$26)*(1-Inputs!$B$20)*(1-Inputs!$B$26/Inputs!$B$27)/($A21-Inputs!$B$26)/(1+$A21)^$H$9+(Inputs!$B$7-Inputs!$B$22-Inputs!$B$10*Inputs!$B$11))/Inputs!$B$6 -> 644.22272 | H21: =(SUMPRODUCT(($D$7:$H$7+H$20*$D$8:$H$8)/(1+$A21)^$D$9:$H$9)+H$20*$H$5*(1+Inputs!$B$26)*(1-Inputs!$B$20)*(1-Inputs!$B$26/Inputs!$B$27)/($A21-Inputs!$B$26)/(1+$A21)^$H$9+(Inputs!$B$7-Inputs!$B$22-Inputs!$B$10*Inputs!$B$11))/Inputs!$B$6 -> 699.55065 | I21: =(SUMPRODUCT(($D$7:$H$7+I$20*$D$8:$H$8)/(1+$A21)^$D$9:$H$9)+I$20*$H$5*(1+Inputs!$B$26)*(1-Inputs!$B$20)*(1-Inputs!$B$26/Inputs!$B$27)/($A21-Inputs!$B$26)/(1+$A21)^$H$9+(Inputs!$B$7-Inputs!$B$22-Inputs!$B$10*Inputs!$B$11))/Inputs!$B$6 -> 810.20653
A22: 0.11 | C22: =(SUMPRODUCT(($D$7:$H$7+C$20*$D$8:$H$8)/(1+$A22)^$D$9:$H$9)+C$20*$H$5*(1+Inputs!$B$26)*(1-Inputs!$B$20)*(1-Inputs!$B$26/Inputs!$B$27)/($A22-Inputs!$B$26)/(1+$A22)^$H$9+(Inputs!$B$7-Inputs!$B$22-Inputs!$B$10*Inputs!$B$11))/Inputs!$B$6 -> 398.79125 | D22: =(SUMPRODUCT(($D$7:$H$7+D$20*$D$8:$H$8)/(1+$A22)^$D$9:$H$9)+D$20*$H$5*(1+Inputs!$B$26)*(1-Inputs!$B$20)*(1-Inputs!$B$26/Inputs!$B$27)/($A22-Inputs!$B$26)/(1+$A22)^$H$9+(Inputs!$B$7-Inputs!$B$22-Inputs!$B$10*Inputs!$B$11))/Inputs!$B$6 -> 446.93564 | E22: =(SUMPRODUCT(($D$7:$H$7+E$20*$D$8:$H$8)/(1+$A22)^$D$9:$H$9)+E$20*$H$5*(1+Inputs!$B$26)*(1-Inputs!$B$20)*(1-Inputs!$B$26/Inputs!$B$27)/($A22-Inputs!$B$26)/(1+$A22)^$H$9+(Inputs!$B$7-Inputs!$B$22-Inputs!$B$10*Inputs!$B$11))/Inputs!$B$6 -> 495.08003 | F22: =(SUMPRODUCT(($D$7:$H$7+F$20*$D$8:$H$8)/(1+$A22)^$D$9:$H$9)+F$20*$H$5*(1+Inputs!$B$26)*(1-Inputs!$B$20)*(1-Inputs!$B$26/Inputs!$B$27)/($A22-Inputs!$B$26)/(1+$A22)^$H$9+(Inputs!$B$7-Inputs!$B$22-Inputs!$B$10*Inputs!$B$11))/Inputs!$B$6 -> 543.22443 | G22: =(SUMPRODUCT(($D$7:$H$7+G$20*$D$8:$H$8)/(1+$A22)^$D$9:$H$9)+G$20*$H$5*(1+Inputs!$B$26)*(1-Inputs!$B$20)*(1-Inputs!$B$26/Inputs!$B$27)/($A22-Inputs!$B$26)/(1+$A22)^$H$9+(Inputs!$B$7-Inputs!$B$22-Inputs!$B$10*Inputs!$B$11))/Inputs!$B$6 -> 591.36882 | H22: =(SUMPRODUCT(($D$7:$H$7+H$20*$D$8:$H$8)/(1+$A22)^$D$9:$H$9)+H$20*$H$5*(1+Inputs!$B$26)*(1-Inputs!$B$20)*(1-Inputs!$B$26/Inputs!$B$27)/($A22-Inputs!$B$26)/(1+$A22)^$H$9+(Inputs!$B$7-Inputs!$B$22-Inputs!$B$10*Inputs!$B$11))/Inputs!$B$6 -> 639.51321 | I22: =(SUMPRODUCT(($D$7:$H$7+I$20*$D$8:$H$8)/(1+$A22)^$D$9:$H$9)+I$20*$H$5*(1+Inputs!$B$26)*(1-Inputs!$B$20)*(1-Inputs!$B$26/Inputs!$B$27)/($A22-Inputs!$B$26)/(1+$A22)^$H$9+(Inputs!$B$7-Inputs!$B$22-Inputs!$B$10*Inputs!$B$11))/Inputs!$B$6 -> 735.80199
A23: 0.12 | C23: =(SUMPRODUCT(($D$7:$H$7+C$20*$D$8:$H$8)/(1+$A23)^$D$9:$H$9)+C$20*$H$5*(1+Inputs!$B$26)*(1-Inputs!$B$20)*(1-Inputs!$B$26/Inputs!$B$27)/($A23-Inputs!$B$26)/(1+$A23)^$H$9+(Inputs!$B$7-Inputs!$B$22-Inputs!$B$10*Inputs!$B$11))/Inputs!$B$6 -> 379.47638 | D23: =(SUMPRODUCT(($D$7:$H$7+D$20*$D$8:$H$8)/(1+$A23)^$D$9:$H$9)+D$20*$H$5*(1+Inputs!$B$26)*(1-Inputs!$B$20)*(1-Inputs!$B$26/Inputs!$B$27)/($A23-Inputs!$B$26)/(1+$A23)^$H$9+(Inputs!$B$7-Inputs!$B$22-Inputs!$B$10*Inputs!$B$11))/Inputs!$B$6 -> 422.02125 | E23: =(SUMPRODUCT(($D$7:$H$7+E$20*$D$8:$H$8)/(1+$A23)^$D$9:$H$9)+E$20*$H$5*(1+Inputs!$B$26)*(1-Inputs!$B$20)*(1-Inputs!$B$26/Inputs!$B$27)/($A23-Inputs!$B$26)/(1+$A23)^$H$9+(Inputs!$B$7-Inputs!$B$22-Inputs!$B$10*Inputs!$B$11))/Inputs!$B$6 -> 464.56613 | F23: =(SUMPRODUCT(($D$7:$H$7+F$20*$D$8:$H$8)/(1+$A23)^$D$9:$H$9)+F$20*$H$5*(1+Inputs!$B$26)*(1-Inputs!$B$20)*(1-Inputs!$B$26/Inputs!$B$27)/($A23-Inputs!$B$26)/(1+$A23)^$H$9+(Inputs!$B$7-Inputs!$B$22-Inputs!$B$10*Inputs!$B$11))/Inputs!$B$6 -> 507.11101 | G23: =(SUMPRODUCT(($D$7:$H$7+G$20*$D$8:$H$8)/(1+$A23)^$D$9:$H$9)+G$20*$H$5*(1+Inputs!$B$26)*(1-Inputs!$B$20)*(1-Inputs!$B$26/Inputs!$B$27)/($A23-Inputs!$B$26)/(1+$A23)^$H$9+(Inputs!$B$7-Inputs!$B$22-Inputs!$B$10*Inputs!$B$11))/Inputs!$B$6 -> 549.65588 | H23: =(SUMPRODUCT(($D$7:$H$7+H$20*$D$8:$H$8)/(1+$A23)^$D$9:$H$9)+H$20*$H$5*(1+Inputs!$B$26)*(1-Inputs!$B$20)*(1-Inputs!$B$26/Inputs!$B$27)/($A23-Inputs!$B$26)/(1+$A23)^$H$9+(Inputs!$B$7-Inputs!$B$22-Inputs!$B$10*Inputs!$B$11))/Inputs!$B$6 -> 592.20076 | I23: =(SUMPRODUCT(($D$7:$H$7+I$20*$D$8:$H$8)/(1+$A23)^$D$9:$H$9)+I$20*$H$5*(1+Inputs!$B$26)*(1-Inputs!$B$20)*(1-Inputs!$B$26/Inputs!$B$27)/($A23-Inputs!$B$26)/(1+$A23)^$H$9+(Inputs!$B$7-Inputs!$B$22-Inputs!$B$10*Inputs!$B$11))/Inputs!$B$6 -> 677.29051
A24: 0.13 | C24: =(SUMPRODUCT(($D$7:$H$7+C$20*$D$8:$H$8)/(1+$A24)^$D$9:$H$9)+C$20*$H$5*(1+Inputs!$B$26)*(1-Inputs!$B$20)*(1-Inputs!$B$26/Inputs!$B$27)/($A24-Inputs!$B$26)/(1+$A24)^$H$9+(Inputs!$B$7-Inputs!$B$22-Inputs!$B$10*Inputs!$B$11))/Inputs!$B$6 -> 363.54278 | D24: =(SUMPRODUCT(($D$7:$H$7+D$20*$D$8:$H$8)/(1+$A24)^$D$9:$H$9)+D$20*$H$5*(1+Inputs!$B$26)*(1-Inputs!$B$20)*(1-Inputs!$B$26/Inputs!$B$27)/($A24-Inputs!$B$26)/(1+$A24)^$H$9+(Inputs!$B$7-Inputs!$B$22-Inputs!$B$10*Inputs!$B$11))/Inputs!$B$6 -> 401.5981 | E24: =(SUMPRODUCT(($D$7:$H$7+E$20*$D$8:$H$8)/(1+$A24)^$D$9:$H$9)+E$20*$H$5*(1+Inputs!$B$26)*(1-Inputs!$B$20)*(1-Inputs!$B$26/Inputs!$B$27)/($A24-Inputs!$B$26)/(1+$A24)^$H$9+(Inputs!$B$7-Inputs!$B$22-Inputs!$B$10*Inputs!$B$11))/Inputs!$B$6 -> 439.65343 | F24: =(SUMPRODUCT(($D$7:$H$7+F$20*$D$8:$H$8)/(1+$A24)^$D$9:$H$9)+F$20*$H$5*(1+Inputs!$B$26)*(1-Inputs!$B$20)*(1-Inputs!$B$26/Inputs!$B$27)/($A24-Inputs!$B$26)/(1+$A24)^$H$9+(Inputs!$B$7-Inputs!$B$22-Inputs!$B$10*Inputs!$B$11))/Inputs!$B$6 -> 477.70876 | G24: =(SUMPRODUCT(($D$7:$H$7+G$20*$D$8:$H$8)/(1+$A24)^$D$9:$H$9)+G$20*$H$5*(1+Inputs!$B$26)*(1-Inputs!$B$20)*(1-Inputs!$B$26/Inputs!$B$27)/($A24-Inputs!$B$26)/(1+$A24)^$H$9+(Inputs!$B$7-Inputs!$B$22-Inputs!$B$10*Inputs!$B$11))/Inputs!$B$6 -> 515.76408 | H24: =(SUMPRODUCT(($D$7:$H$7+H$20*$D$8:$H$8)/(1+$A24)^$D$9:$H$9)+H$20*$H$5*(1+Inputs!$B$26)*(1-Inputs!$B$20)*(1-Inputs!$B$26/Inputs!$B$27)/($A24-Inputs!$B$26)/(1+$A24)^$H$9+(Inputs!$B$7-Inputs!$B$22-Inputs!$B$10*Inputs!$B$11))/Inputs!$B$6 -> 553.81941 | I24: =(SUMPRODUCT(($D$7:$H$7+I$20*$D$8:$H$8)/(1+$A24)^$D$9:$H$9)+I$20*$H$5*(1+Inputs!$B$26)*(1-Inputs!$B$20)*(1-Inputs!$B$26/Inputs!$B$27)/($A24-Inputs!$B$26)/(1+$A24)^$H$9+(Inputs!$B$7-Inputs!$B$22-Inputs!$B$10*Inputs!$B$11))/Inputs!$B$6 -> 629.93006
A25: 0.14 | C25: =(SUMPRODUCT(($D$7:$H$7+C$20*$D$8:$H$8)/(1+$A25)^$D$9:$H$9)+C$20*$H$5*(1+Inputs!$B$26)*(1-Inputs!$B$20)*(1-Inputs!$B$26/Inputs!$B$27)/($A25-Inputs!$B$26)/(1+$A25)^$H$9+(Inputs!$B$7-Inputs!$B$22-Inputs!$B$10*Inputs!$B$11))/Inputs!$B$6 -> 350.08382 | D25: =(SUMPRODUCT(($D$7:$H$7+D$20*$D$8:$H$8)/(1+$A25)^$D$9:$H$9)+D$20*$H$5*(1+Inputs!$B$26)*(1-Inputs!$B$20)*(1-Inputs!$B$26/Inputs!$B$27)/($A25-Inputs!$B$26)/(1+$A25)^$H$9+(Inputs!$B$7-Inputs!$B$22-Inputs!$B$10*Inputs!$B$11))/Inputs!$B$6 -> 384.4578 | E25: =(SUMPRODUCT(($D$7:$H$7+E$20*$D$8:$H$8)/(1+$A25)^$D$9:$H$9)+E$20*$H$5*(1+Inputs!$B$26)*(1-Inputs!$B$20)*(1-Inputs!$B$26/Inputs!$B$27)/($A25-Inputs!$B$26)/(1+$A25)^$H$9+(Inputs!$B$7-Inputs!$B$22-Inputs!$B$10*Inputs!$B$11))/Inputs!$B$6 -> 418.83179 | F25: =(SUMPRODUCT(($D$7:$H$7+F$20*$D$8:$H$8)/(1+$A25)^$D$9:$H$9)+F$20*$H$5*(1+Inputs!$B$26)*(1-Inputs!$B$20)*(1-Inputs!$B$26/Inputs!$B$27)/($A25-Inputs!$B$26)/(1+$A25)^$H$9+(Inputs!$B$7-Inputs!$B$22-Inputs!$B$10*Inputs!$B$11))/Inputs!$B$6 -> 453.20577 | G25: =(SUMPRODUCT(($D$7:$H$7+G$20*$D$8:$H$8)/(1+$A25)^$D$9:$H$9)+G$20*$H$5*(1+Inputs!$B$26)*(1-Inputs!$B$20)*(1-Inputs!$B$26/Inputs!$B$27)/($A25-Inputs!$B$26)/(1+$A25)^$H$9+(Inputs!$B$7-Inputs!$B$22-Inputs!$B$10*Inputs!$B$11))/Inputs!$B$6 -> 487.57976 | H25: =(SUMPRODUCT(($D$7:$H$7+H$20*$D$8:$H$8)/(1+$A25)^$D$9:$H$9)+H$20*$H$5*(1+Inputs!$B$26)*(1-Inputs!$B$20)*(1-Inputs!$B$26/Inputs!$B$27)/($A25-Inputs!$B$26)/(1+$A25)^$H$9+(Inputs!$B$7-Inputs!$B$22-Inputs!$B$10*Inputs!$B$11))/Inputs!$B$6 -> 521.95374 | I25: =(SUMPRODUCT(($D$7:$H$7+I$20*$D$8:$H$8)/(1+$A25)^$D$9:$H$9)+I$20*$H$5*(1+Inputs!$B$26)*(1-Inputs!$B$20)*(1-Inputs!$B$26/Inputs!$B$27)/($A25-Inputs!$B$26)/(1+$A25)^$H$9+(Inputs!$B$7-Inputs!$B$22-Inputs!$B$10*Inputs!$B$11))/Inputs!$B$6 -> 590.70171
A26: 0.15 | C26: =(SUMPRODUCT(($D$7:$H$7+C$20*$D$8:$H$8)/(1+$A26)^$D$9:$H$9)+C$20*$H$5*(1+Inputs!$B$26)*(1-Inputs!$B$20)*(1-Inputs!$B$26/Inputs!$B$27)/($A26-Inputs!$B$26)/(1+$A26)^$H$9+(Inputs!$B$7-Inputs!$B$22-Inputs!$B$10*Inputs!$B$11))/Inputs!$B$6 -> 338.49446 | D26: =(SUMPRODUCT(($D$7:$H$7+D$20*$D$8:$H$8)/(1+$A26)^$D$9:$H$9)+D$20*$H$5*(1+Inputs!$B$26)*(1-Inputs!$B$20)*(1-Inputs!$B$26/Inputs!$B$27)/($A26-Inputs!$B$26)/(1+$A26)^$H$9+(Inputs!$B$7-Inputs!$B$22-Inputs!$B$10*Inputs!$B$11))/Inputs!$B$6 -> 369.79407 | E26: =(SUMPRODUCT(($D$7:$H$7+E$20*$D$8:$H$8)/(1+$A26)^$D$9:$H$9)+E$20*$H$5*(1+Inputs!$B$26)*(1-Inputs!$B$20)*(1-Inputs!$B$26/Inputs!$B$27)/($A26-Inputs!$B$26)/(1+$A26)^$H$9+(Inputs!$B$7-Inputs!$B$22-Inputs!$B$10*Inputs!$B$11))/Inputs!$B$6 -> 401.09368 | F26: =(SUMPRODUCT(($D$7:$H$7+F$20*$D$8:$H$8)/(1+$A26)^$D$9:$H$9)+F$20*$H$5*(1+Inputs!$B$26)*(1-Inputs!$B$20)*(1-Inputs!$B$26/Inputs!$B$27)/($A26-Inputs!$B$26)/(1+$A26)^$H$9+(Inputs!$B$7-Inputs!$B$22-Inputs!$B$10*Inputs!$B$11))/Inputs!$B$6 -> 432.39329 | G26: =(SUMPRODUCT(($D$7:$H$7+G$20*$D$8:$H$8)/(1+$A26)^$D$9:$H$9)+G$20*$H$5*(1+Inputs!$B$26)*(1-Inputs!$B$20)*(1-Inputs!$B$26/Inputs!$B$27)/($A26-Inputs!$B$26)/(1+$A26)^$H$9+(Inputs!$B$7-Inputs!$B$22-Inputs!$B$10*Inputs!$B$11))/Inputs!$B$6 -> 463.6929 | H26: =(SUMPRODUCT(($D$7:$H$7+H$20*$D$8:$H$8)/(1+$A26)^$D$9:$H$9)+H$20*$H$5*(1+Inputs!$B$26)*(1-Inputs!$B$20)*(1-Inputs!$B$26/Inputs!$B$27)/($A26-Inputs!$B$26)/(1+$A26)^$H$9+(Inputs!$B$7-Inputs!$B$22-Inputs!$B$10*Inputs!$B$11))/Inputs!$B$6 -> 494.99251 | I26: =(SUMPRODUCT(($D$7:$H$7+I$20*$D$8:$H$8)/(1+$A26)^$D$9:$H$9)+I$20*$H$5*(1+Inputs!$B$26)*(1-Inputs!$B$20)*(1-Inputs!$B$26/Inputs!$B$27)/($A26-Inputs!$B$26)/(1+$A26)^$H$9+(Inputs!$B$7-Inputs!$B$22-Inputs!$B$10*Inputs!$B$11))/Inputs!$B$6 -> 557.59172
A27: 0.16 | C27: =(SUMPRODUCT(($D$7:$H$7+C$20*$D$8:$H$8)/(1+$A27)^$D$9:$H$9)+C$20*$H$5*(1+Inputs!$B$26)*(1-Inputs!$B$20)*(1-Inputs!$B$26/Inputs!$B$27)/($A27-Inputs!$B$26)/(1+$A27)^$H$9+(Inputs!$B$7-Inputs!$B$22-Inputs!$B$10*Inputs!$B$11))/Inputs!$B$6 -> 328.3553 | D27: =(SUMPRODUCT(($D$7:$H$7+D$20*$D$8:$H$8)/(1+$A27)^$D$9:$H$9)+D$20*$H$5*(1+Inputs!$B$26)*(1-Inputs!$B$20)*(1-Inputs!$B$26/Inputs!$B$27)/($A27-Inputs!$B$26)/(1+$A27)^$H$9+(Inputs!$B$7-Inputs!$B$22-Inputs!$B$10*Inputs!$B$11))/Inputs!$B$6 -> 357.04812 | E27: =(SUMPRODUCT(($D$7:$H$7+E$20*$D$8:$H$8)/(1+$A27)^$D$9:$H$9)+E$20*$H$5*(1+Inputs!$B$26)*(1-Inputs!$B$20)*(1-Inputs!$B$26/Inputs!$B$27)/($A27-Inputs!$B$26)/(1+$A27)^$H$9+(Inputs!$B$7-Inputs!$B$22-Inputs!$B$10*Inputs!$B$11))/Inputs!$B$6 -> 385.74093 | F27: =(SUMPRODUCT(($D$7:$H$7+F$20*$D$8:$H$8)/(1+$A27)^$D$9:$H$9)+F$20*$H$5*(1+Inputs!$B$26)*(1-Inputs!$B$20)*(1-Inputs!$B$26/Inputs!$B$27)/($A27-Inputs!$B$26)/(1+$A27)^$H$9+(Inputs!$B$7-Inputs!$B$22-Inputs!$B$10*Inputs!$B$11))/Inputs!$B$6 -> 414.43375 | G27: =(SUMPRODUCT(($D$7:$H$7+G$20*$D$8:$H$8)/(1+$A27)^$D$9:$H$9)+G$20*$H$5*(1+Inputs!$B$26)*(1-Inputs!$B$20)*(1-Inputs!$B$26/Inputs!$B$27)/($A27-Inputs!$B$26)/(1+$A27)^$H$9+(Inputs!$B$7-Inputs!$B$22-Inputs!$B$10*Inputs!$B$11))/Inputs!$B$6 -> 443.12657 | H27: =(SUMPRODUCT(($D$7:$H$7+H$20*$D$8:$H$8)/(1+$A27)^$D$9:$H$9)+H$20*$H$5*(1+Inputs!$B$26)*(1-Inputs!$B$20)*(1-Inputs!$B$26/Inputs!$B$27)/($A27-Inputs!$B$26)/(1+$A27)^$H$9+(Inputs!$B$7-Inputs!$B$22-Inputs!$B$10*Inputs!$B$11))/Inputs!$B$6 -> 471.81938 | I27: =(SUMPRODUCT(($D$7:$H$7+I$20*$D$8:$H$8)/(1+$A27)^$D$9:$H$9)+I$20*$H$5*(1+Inputs!$B$26)*(1-Inputs!$B$20)*(1-Inputs!$B$26/Inputs!$B$27)/($A27-Inputs!$B$26)/(1+$A27)^$H$9+(Inputs!$B$7-Inputs!$B$22-Inputs!$B$10*Inputs!$B$11))/Inputs!$B$6 -> 529.20501
A28: 0.18 | C28: =(SUMPRODUCT(($D$7:$H$7+C$20*$D$8:$H$8)/(1+$A28)^$D$9:$H$9)+C$20*$H$5*(1+Inputs!$B$26)*(1-Inputs!$B$20)*(1-Inputs!$B$26/Inputs!$B$27)/($A28-Inputs!$B$26)/(1+$A28)^$H$9+(Inputs!$B$7-Inputs!$B$22-Inputs!$B$10*Inputs!$B$11))/Inputs!$B$6 -> 311.3069 | D28: =(SUMPRODUCT(($D$7:$H$7+D$20*$D$8:$H$8)/(1+$A28)^$D$9:$H$9)+D$20*$H$5*(1+Inputs!$B$26)*(1-Inputs!$B$20)*(1-Inputs!$B$26/Inputs!$B$27)/($A28-Inputs!$B$26)/(1+$A28)^$H$9+(Inputs!$B$7-Inputs!$B$22-Inputs!$B$10*Inputs!$B$11))/Inputs!$B$6 -> 335.81697 | E28: =(SUMPRODUCT(($D$7:$H$7+E$20*$D$8:$H$8)/(1+$A28)^$D$9:$H$9)+E$20*$H$5*(1+Inputs!$B$26)*(1-Inputs!$B$20)*(1-Inputs!$B$26/Inputs!$B$27)/($A28-Inputs!$B$26)/(1+$A28)^$H$9+(Inputs!$B$7-Inputs!$B$22-Inputs!$B$10*Inputs!$B$11))/Inputs!$B$6 -> 360.32703 | F28: =(SUMPRODUCT(($D$7:$H$7+F$20*$D$8:$H$8)/(1+$A28)^$D$9:$H$9)+F$20*$H$5*(1+Inputs!$B$26)*(1-Inputs!$B$20)*(1-Inputs!$B$26/Inputs!$B$27)/($A28-Inputs!$B$26)/(1+$A28)^$H$9+(Inputs!$B$7-Inputs!$B$22-Inputs!$B$10*Inputs!$B$11))/Inputs!$B$6 -> 384.8371 | G28: =(SUMPRODUCT(($D$7:$H$7+G$20*$D$8:$H$8)/(1+$A28)^$D$9:$H$9)+G$20*$H$5*(1+Inputs!$B$26)*(1-Inputs!$B$20)*(1-Inputs!$B$26/Inputs!$B$27)/($A28-Inputs!$B$26)/(1+$A28)^$H$9+(Inputs!$B$7-Inputs!$B$22-Inputs!$B$10*Inputs!$B$11))/Inputs!$B$6 -> 409.34716 | H28: =(SUMPRODUCT(($D$7:$H$7+H$20*$D$8:$H$8)/(1+$A28)^$D$9:$H$9)+H$20*$H$5*(1+Inputs!$B$26)*(1-Inputs!$B$20)*(1-Inputs!$B$26/Inputs!$B$27)/($A28-Inputs!$B$26)/(1+$A28)^$H$9+(Inputs!$B$7-Inputs!$B$22-Inputs!$B$10*Inputs!$B$11))/Inputs!$B$6 -> 433.85723 | I28: =(SUMPRODUCT(($D$7:$H$7+I$20*$D$8:$H$8)/(1+$A28)^$D$9:$H$9)+I$20*$H$5*(1+Inputs!$B$26)*(1-Inputs!$B$20)*(1-Inputs!$B$26/Inputs!$B$27)/($A28-Inputs!$B$26)/(1+$A28)^$H$9+(Inputs!$B$7-Inputs!$B$22-Inputs!$B$10*Inputs!$B$11))/Inputs!$B$6 -> 482.87736
A30: Current price ($) | C30: =Inputs!B5 -> 878.84
A31: Model WACC | C31: =Inputs!B23 -> 0.14171708

Sheet Comps
A1: Memory and storage peers. Source: Yahoo Finance via yfinance, 2026-10-16 (multiples are currency-neutral).
A2: Peak-cycle earnings make every P/E in the group look cheap: compare multiples within the cycle, not with the market.
A4: Company | B4: Ticker | C4: Trailing P/E | D4: Forward P/E | E4: EV / EBITDA | F4: EV / revenue | G4: Operating margin | H4: Gross margin
A5: Micron | B5: MU | C5: 11.8 | D5: 4.2 | E5: 8.8 | F5: 7.2 | G5: 0.807 | H5: 0.807
A6: SK hynix | B6: 000660.KS | C6: n/a | D6: 2.7 | E6: 5.8 | F6: 4.4 | G6: 0.763 | H6: 0.763
A7: Samsung Electronics | B7: 005930.KS | C7: n/a | D7: 3 | E7: 5.6 | F7: 2.6 | G7: 0.522 | H7: 0.575
A8: Sandisk | B8: SNDK | C8: 17.6 | D8: 4.9 | E8: 14.7 | F8: 9.2 | G8: 0.785 | H8: 0.715
A9: Western Digital | B9: WDC | C9: 12.3 | D9: 10 | E9: 23.9 | F9: 9.2 | G9: 0.436 | H9: 0.489
A10: Seagate | B10: STX | C10: 46 | D10: 11.3 | E10: 32.7 | F10: 12.1 | G10: 0.431 | H10: 0.456
A12: Median, peers excl. Micron | C12: =MEDIAN(C6:C10) -> 17.6 | D12: =MEDIAN(D6:D10) -> 4.9 | E12: =MEDIAN(E6:E10) -> 14.7 | F12: =MEDIAN(F6:F10) -> 9.2 | G12: =MEDIAN(G6:G10) -> 0.522 | H12: =MEDIAN(H6:H10) -> 0.575
A13: Micron forward P/E vs peer median | D13: =D5/D12-1 -> -0.14285714
